Workbook
Name ReceiptCategoryList: #REF!
Name 가예산: Table_9[가예산]
Name 교육선전: Table_3[교육선전]
Name 대외협력: Table_4[대외협력]
Name 선대본: '3. 5기 수입지출장부'!$F$178:$F$181
Name 수입: Table_8[수입]
Name 정책기획: Table_5[정책기획]
Name 조직강화: Table_6[조직강화]
Name 총무: Table_2[총무]

Sheet 1. 5기추진일정
B4: 구 분 | C4: 내 용 | E4: 2026년 | Q4: 예산 (단위:원) | S4: 실적 | T4: 비고
E5: 1 | F5: 2 | G5: 3 | H5: 4 | I5: 5 | J5: 6 | K5: 7 | L5: 8 | M5: 9 | N5: 10 | O5: 11 | P5: 12
B6: 1 | C6: 경조금 | D6: 계획 | Q6: ='2. 5기_예산목간'!D24 -> 3300000 | S6: =Q7/Q6 -> 0.24242424 | T6: 총무부 | X6: 총무부 | Y6: 조강부 | Z6: 정책 | AA6: 대협 | AB6: 교선 | AC6: 계
D7: 실적 | E7: =IF(COUNTIFS('3. 5기 수입지출장부'!$C$5:$C$2003,$C6,'3. 5기 수입지출장부'!$A$5:$A$2003,">="&DATE(2026,E$5,1),'3. 5기 수입지출장부'!$A$5:$A$2003,"<"&DATE(2026,E$5+1,1),'3. 5기 수입지출장부'!$E$5:$E$2003,">0")>0,"■","") | F7: =IF(COUNTIFS('3. 5기 수입지출장부'!$C$5:$C$2003,$C6,'3. 5기 수입지출장부'!$A$5:$A$2003,">="&DATE(2026,F$5,1),'3. 5기 수입지출장부'!$A$5:$A$2003,"<"&DATE(2026,F$5+1,1),'3. 5기 수입지출장부'!$E$5:$E$2003,">0")>0,"■","") | G7: =IF(COUNTIFS('3. 5기 수입지출장부'!$C$5:$C$2003,$C6,'3. 5기 수입지출장부'!$A$5:$A$2003,">="&DATE(2026,G$5,1),'3. 5기 수입지출장부'!$A$5:$A$2003,"<"&DATE(2026,G$5+1,1),'3. 5기 수입지출장부'!$E$5:$E$2003,">0")>0,"■","") -> ■ | H7: =IF(COUNTIFS('3. 5기 수입지출장부'!$C$5:$C$2003,$C6,'3. 5기 수입지출장부'!$A$5:$A$2003,">="&DATE(2026,H$5,1),'3. 5기 수입지출장부'!$A$5:$A$2003,"<"&DATE(2026,H$5+1,1),'3. 5기 수입지출장부'!$E$5:$E$2003,">0")>0,"■","") | I7: =IF(COUNTIFS('3. 5기 수입지출장부'!$C$5:$C$2003,$C6,'3. 5기 수입지출장부'!$A$5:$A$2003,">="&DATE(2026,I$5,1),'3. 5기 수입지출장부'!$A$5:$A$2003,"<"&DATE(2026,I$5+1,1),'3. 5기 수입지출장부'!$E$5:$E$2003,">0")>0,"■","") | J7: =IF(COUNTIFS('3. 5기 수입지출장부'!$C$5:$C$2003,$C6,'3. 5기 수입지출장부'!$A$5:$A$2003,">="&DATE(2026,J$5,1),'3. 5기 수입지출장부'!$A$5:$A$2003,"<"&DATE(2026,J$5+1,1),'3. 5기 수입지출장부'!$E$5:$E$2003,">0")>0,"■","") -> ■ | K7: =IF(COUNTIFS('3. 5기 수입지출장부'!$C$5:$C$2003,$C6,'3. 5기 수입지출장부'!$A$5:$A$2003,">="&DATE(2026,K$5,1),'3. 5기 수입지출장부'!$A$5:$A$2003,"<"&DATE(2026,K$5+1,1),'3. 5기 수입지출장부'!$E$5:$E$2003,">0")>0,"■","") -> ■ | L7: =IF(COUNTIFS('3. 5기 수입지출장부'!$C$5:$C$2003,$C6,'3. 5기 수입지출장부'!$A$5:$A$2003,">="&DATE(2026,L$5,1),'3. 5기 수입지출장부'!$A$5:$A$2003,"<"&DATE(2026,L$5+1,1),'3. 5기 수입지출장부'!$E$5:$E$2003,">0")>0,"■","") | ... P7: =IF(COUNTIFS('3. 5기 수입지출장부'!$C$5:$C$2003,$C6,'3. 5기 수입지출장부'!$A$5:$A$2003,">="&DATE(2026,P$5,1),'3. 5기 수입지출장부'!$A$5:$A$2003,"<"&DATE(2026,P$5+1,1),'3. 5기 수입지출장부'!$E$5:$E$2003,">0")>0,"■","") | Q7: ='3. 5기 수입지출장부'!E192 -> 800000 | X7: =SUM(Q6,Q8,Q10,Q22,Q46,Q26,Q42,Q44) -> 23118091 | Y7: =SUM(Q14,Q24,Q28,Q30,Q32) -> 14700000 | Z7: =SUM(Q16,Q34) -> 800000 | AA7: =SUM(Q18,Q36) -> 500000 | AB7: =SUM(Q20,Q40,Q38) -> 1100000 | AC7: =SUM(X7:AB7) -> 40218091
B8: 2 | C8: 국내여비 | D8: 계획 | Q8: ='2. 5기_예산목간'!D26 -> 1927800 | S8: =Q9/Q8 -> 0 | T8: 총무부
D9: 실적 | E9: =IF(COUNTIFS('3. 5기 수입지출장부'!$C$5:$C$2003,$C8,'3. 5기 수입지출장부'!$A$5:$A$2003,">="&DATE(2026,E$5,1),'3. 5기 수입지출장부'!$A$5:$A$2003,"<"&DATE(2026,E$5+1,1),'3. 5기 수입지출장부'!$E$5:$E$2003,">0")>0,"■","") | F9: =IF(COUNTIFS('3. 5기 수입지출장부'!$C$5:$C$2003,$C8,'3. 5기 수입지출장부'!$A$5:$A$2003,">="&DATE(2026,F$5,1),'3. 5기 수입지출장부'!$A$5:$A$2003,"<"&DATE(2026,F$5+1,1),'3. 5기 수입지출장부'!$E$5:$E$2003,">0")>0,"■","") | G9: =IF(COUNTIFS('3. 5기 수입지출장부'!$C$5:$C$2003,$C8,'3. 5기 수입지출장부'!$A$5:$A$2003,">="&DATE(2026,G$5,1),'3. 5기 수입지출장부'!$A$5:$A$2003,"<"&DATE(2026,G$5+1,1),'3. 5기 수입지출장부'!$E$5:$E$2003,">0")>0,"■","") | H9: =IF(COUNTIFS('3. 5기 수입지출장부'!$C$5:$C$2003,$C8,'3. 5기 수입지출장부'!$A$5:$A$2003,">="&DATE(2026,H$5,1),'3. 5기 수입지출장부'!$A$5:$A$2003,"<"&DATE(2026,H$5+1,1),'3. 5기 수입지출장부'!$E$5:$E$2003,">0")>0,"■","") | I9: =IF(COUNTIFS('3. 5기 수입지출장부'!$C$5:$C$2003,$C8,'3. 5기 수입지출장부'!$A$5:$A$2003,">="&DATE(2026,I$5,1),'3. 5기 수입지출장부'!$A$5:$A$2003,"<"&DATE(2026,I$5+1,1),'3. 5기 수입지출장부'!$E$5:$E$2003,">0")>0,"■","") | J9: =IF(COUNTIFS('3. 5기 수입지출장부'!$C$5:$C$2003,$C8,'3. 5기 수입지출장부'!$A$5:$A$2003,">="&DATE(2026,J$5,1),'3. 5기 수입지출장부'!$A$5:$A$2003,"<"&DATE(2026,J$5+1,1),'3. 5기 수입지출장부'!$E$5:$E$2003,">0")>0,"■","") | K9: =IF(COUNTIFS('3. 5기 수입지출장부'!$C$5:$C$2003,$C8,'3. 5기 수입지출장부'!$A$5:$A$2003,">="&DATE(2026,K$5,1),'3. 5기 수입지출장부'!$A$5:$A$2003,"<"&DATE(2026,K$5+1,1),'3. 5기 수입지출장부'!$E$5:$E$2003,">0")>0,"■","") | L9: =IF(COUNTIFS('3. 5기 수입지출장부'!$C$5:$C$2003,$C8,'3. 5기 수입지출장부'!$A$5:$A$2003,">="&DATE(2026,L$5,1),'3. 5기 수입지출장부'!$A$5:$A$2003,"<"&DATE(2026,L$5+1,1),'3. 5기 수입지출장부'!$E$5:$E$2003,">0")>0,"■","") | ... P9: =IF(COUNTIFS('3. 5기 수입지출장부'!$C$5:$C$2003,$C8,'3. 5기 수입지출장부'!$A$5:$A$2003,">="&DATE(2026,P$5,1),'3. 5기 수입지출장부'!$A$5:$A$2003,"<"&DATE(2026,P$5+1,1),'3. 5기 수입지출장부'!$E$5:$E$2003,">0")>0,"■","") | Q9: ='3. 5기 수입지출장부'!E193 -> 0
B10: =B8+1 -> 3 | C10: 운영위원회의비 | D10: 계획 | Q10: ='2. 5기_예산목간'!D27 -> 540000 | S10: =Q11/Q10 -> 0.30740741 | T10: 총무부
D11: 실적 | E11: =IF(COUNTIFS('3. 5기 수입지출장부'!$C$5:$C$2003,$C10,'3. 5기 수입지출장부'!$A$5:$A$2003,">="&DATE(2026,E$5,1),'3. 5기 수입지출장부'!$A$5:$A$2003,"<"&DATE(2026,E$5+1,1),'3. 5기 수입지출장부'!$E$5:$E$2003,">0")>0,"■","") | F11: =IF(COUNTIFS('3. 5기 수입지출장부'!$C$5:$C$2003,$C10,'3. 5기 수입지출장부'!$A$5:$A$2003,">="&DATE(2026,F$5,1),'3. 5기 수입지출장부'!$A$5:$A$2003,"<"&DATE(2026,F$5+1,1),'3. 5기 수입지출장부'!$E$5:$E$2003,">0")>0,"■","") | G11: =IF(COUNTIFS('3. 5기 수입지출장부'!$C$5:$C$2003,$C10,'3. 5기 수입지출장부'!$A$5:$A$2003,">="&DATE(2026,G$5,1),'3. 5기 수입지출장부'!$A$5:$A$2003,"<"&DATE(2026,G$5+1,1),'3. 5기 수입지출장부'!$E$5:$E$2003,">0")>0,"■","") | H11: =IF(COUNTIFS('3. 5기 수입지출장부'!$C$5:$C$2003,$C10,'3. 5기 수입지출장부'!$A$5:$A$2003,">="&DATE(2026,H$5,1),'3. 5기 수입지출장부'!$A$5:$A$2003,"<"&DATE(2026,H$5+1,1),'3. 5기 수입지출장부'!$E$5:$E$2003,">0")>0,"■","") -> ■ | I11: =IF(COUNTIFS('3. 5기 수입지출장부'!$C$5:$C$2003,$C10,'3. 5기 수입지출장부'!$A$5:$A$2003,">="&DATE(2026,I$5,1),'3. 5기 수입지출장부'!$A$5:$A$2003,"<"&DATE(2026,I$5+1,1),'3. 5기 수입지출장부'!$E$5:$E$2003,">0")>0,"■","") | J11: =IF(COUNTIFS('3. 5기 수입지출장부'!$C$5:$C$2003,$C10,'3. 5기 수입지출장부'!$A$5:$A$2003,">="&DATE(2026,J$5,1),'3. 5기 수입지출장부'!$A$5:$A$2003,"<"&DATE(2026,J$5+1,1),'3. 5기 수입지출장부'!$E$5:$E$2003,">0")>0,"■","") | K11: =IF(COUNTIFS('3. 5기 수입지출장부'!$C$5:$C$2003,$C10,'3. 5기 수입지출장부'!$A$5:$A$2003,">="&DATE(2026,K$5,1),'3. 5기 수입지출장부'!$A$5:$A$2003,"<"&DATE(2026,K$5+1,1),'3. 5기 수입지출장부'!$E$5:$E$2003,">0")>0,"■","") | L11: =IF(COUNTIFS('3. 5기 수입지출장부'!$C$5:$C$2003,$C10,'3. 5기 수입지출장부'!$A$5:$A$2003,">="&DATE(2026,L$5,1),'3. 5기 수입지출장부'!$A$5:$A$2003,"<"&DATE(2026,L$5+1,1),'3. 5기 수입지출장부'!$E$5:$E$2003,">0")>0,"■","") | ... P11: =IF(COUNTIFS('3. 5기 수입지출장부'!$C$5:$C$2003,$C10,'3. 5기 수입지출장부'!$A$5:$A$2003,">="&DATE(2026,P$5,1),'3. 5기 수입지출장부'!$A$5:$A$2003,"<"&DATE(2026,P$5+1,1),'3. 5기 수입지출장부'!$E$5:$E$2003,">0")>0,"■","") | Q11: ='3. 5기 수입지출장부'!E194 -> 166000
B12: 4 | C12: 대의원선거비 | D12: 계획 | Q12: ='2. 5기_예산목간'!D28 -> 1000000 | S12: =Q13/Q12 -> 0
D13: 실적 | E13: =IF(COUNTIFS('3. 5기 수입지출장부'!$C$5:$C$2003,$C12,'3. 5기 수입지출장부'!$A$5:$A$2003,">="&DATE(2026,E$5,1),'3. 5기 수입지출장부'!$A$5:$A$2003,"<"&DATE(2026,E$5+1,1),'3. 5기 수입지출장부'!$E$5:$E$2003,">0")>0,"■","") | F13: =IF(COUNTIFS('3. 5기 수입지출장부'!$C$5:$C$2003,$C12,'3. 5기 수입지출장부'!$A$5:$A$2003,">="&DATE(2026,F$5,1),'3. 5기 수입지출장부'!$A$5:$A$2003,"<"&DATE(2026,F$5+1,1),'3. 5기 수입지출장부'!$E$5:$E$2003,">0")>0,"■","") | G13: =IF(COUNTIFS('3. 5기 수입지출장부'!$C$5:$C$2003,$C12,'3. 5기 수입지출장부'!$A$5:$A$2003,">="&DATE(2026,G$5,1),'3. 5기 수입지출장부'!$A$5:$A$2003,"<"&DATE(2026,G$5+1,1),'3. 5기 수입지출장부'!$E$5:$E$2003,">0")>0,"■","") | H13: =IF(COUNTIFS('3. 5기 수입지출장부'!$C$5:$C$2003,$C12,'3. 5기 수입지출장부'!$A$5:$A$2003,">="&DATE(2026,H$5,1),'3. 5기 수입지출장부'!$A$5:$A$2003,"<"&DATE(2026,H$5+1,1),'3. 5기 수입지출장부'!$E$5:$E$2003,">0")>0,"■","") | I13: =IF(COUNTIFS('3. 5기 수입지출장부'!$C$5:$C$2003,$C12,'3. 5기 수입지출장부'!$A$5:$A$2003,">="&DATE(2026,I$5,1),'3. 5기 수입지출장부'!$A$5:$A$2003,"<"&DATE(2026,I$5+1,1),'3. 5기 수입지출장부'!$E$5:$E$2003,">0")>0,"■","") | J13: =IF(COUNTIFS('3. 5기 수입지출장부'!$C$5:$C$2003,$C12,'3. 5기 수입지출장부'!$A$5:$A$2003,">="&DATE(2026,J$5,1),'3. 5기 수입지출장부'!$A$5:$A$2003,"<"&DATE(2026,J$5+1,1),'3. 5기 수입지출장부'!$E$5:$E$2003,">0")>0,"■","") | K13: =IF(COUNTIFS('3. 5기 수입지출장부'!$C$5:$C$2003,$C12,'3. 5기 수입지출장부'!$A$5:$A$2003,">="&DATE(2026,K$5,1),'3. 5기 수입지출장부'!$A$5:$A$2003,"<"&DATE(2026,K$5+1,1),'3. 5기 수입지출장부'!$E$5:$E$2003,">0")>0,"■","") | L13: =IF(COUNTIFS('3. 5기 수입지출장부'!$C$5:$C$2003,$C12,'3. 5기 수입지출장부'!$A$5:$A$2003,">="&DATE(2026,L$5,1),'3. 5기 수입지출장부'!$A$5:$A$2003,"<"&DATE(2026,L$5+1,1),'3. 5기 수입지출장부'!$E$5:$E$2003,">0")>0,"■","") | ... P13: =IF(COUNTIFS('3. 5기 수입지출장부'!$C$5:$C$2003,$C12,'3. 5기 수입지출장부'!$A$5:$A$2003,">="&DATE(2026,P$5,1),'3. 5기 수입지출장부'!$A$5:$A$2003,"<"&DATE(2026,P$5+1,1),'3. 5기 수입지출장부'!$E$5:$E$2003,">0")>0,"■","") | Q13: ='3. 5기 수입지출장부'!E195 -> 0
B14: 5 | C14: 조직부회의비 | D14: 계획 | Q14: ='2. 5기_예산목간'!D29 -> 400000 | S14: =Q15/Q14 -> 0.94 | T14: 조직부
D15: 실적 | E15: =IF(COUNTIFS('3. 5기 수입지출장부'!$C$5:$C$2003,$C14,'3. 5기 수입지출장부'!$A$5:$A$2003,">="&DATE(2026,E$5,1),'3. 5기 수입지출장부'!$A$5:$A$2003,"<"&DATE(2026,E$5+1,1),'3. 5기 수입지출장부'!$E$5:$E$2003,">0")>0,"■","") | F15: =IF(COUNTIFS('3. 5기 수입지출장부'!$C$5:$C$2003,$C14,'3. 5기 수입지출장부'!$A$5:$A$2003,">="&DATE(2026,F$5,1),'3. 5기 수입지출장부'!$A$5:$A$2003,"<"&DATE(2026,F$5+1,1),'3. 5기 수입지출장부'!$E$5:$E$2003,">0")>0,"■","") | G15: =IF(COUNTIFS('3. 5기 수입지출장부'!$C$5:$C$2003,$C14,'3. 5기 수입지출장부'!$A$5:$A$2003,">="&DATE(2026,G$5,1),'3. 5기 수입지출장부'!$A$5:$A$2003,"<"&DATE(2026,G$5+1,1),'3. 5기 수입지출장부'!$E$5:$E$2003,">0")>0,"■","") | H15: =IF(COUNTIFS('3. 5기 수입지출장부'!$C$5:$C$2003,$C14,'3. 5기 수입지출장부'!$A$5:$A$2003,">="&DATE(2026,H$5,1),'3. 5기 수입지출장부'!$A$5:$A$2003,"<"&DATE(2026,H$5+1,1),'3. 5기 수입지출장부'!$E$5:$E$2003,">0")>0,"■","") | I15: =IF(COUNTIFS('3. 5기 수입지출장부'!$C$5:$C$2003,$C14,'3. 5기 수입지출장부'!$A$5:$A$2003,">="&DATE(2026,I$5,1),'3. 5기 수입지출장부'!$A$5:$A$2003,"<"&DATE(2026,I$5+1,1),'3. 5기 수입지출장부'!$E$5:$E$2003,">0")>0,"■","") | J15: =IF(COUNTIFS('3. 5기 수입지출장부'!$C$5:$C$2003,$C14,'3. 5기 수입지출장부'!$A$5:$A$2003,">="&DATE(2026,J$5,1),'3. 5기 수입지출장부'!$A$5:$A$2003,"<"&DATE(2026,J$5+1,1),'3. 5기 수입지출장부'!$E$5:$E$2003,">0")>0,"■","") | K15: =IF(COUNTIFS('3. 5기 수입지출장부'!$C$5:$C$2003,$C14,'3. 5기 수입지출장부'!$A$5:$A$2003,">="&DATE(2026,K$5,1),'3. 5기 수입지출장부'!$A$5:$A$2003,"<"&DATE(2026,K$5+1,1),'3. 5기 수입지출장부'!$E$5:$E$2003,">0")>0,"■","") | L15: =IF(COUNTIFS('3. 5기 수입지출장부'!$C$5:$C$2003,$C14,'3. 5기 수입지출장부'!$A$5:$A$2003,">="&DATE(2026,L$5,1),'3. 5기 수입지출장부'!$A$5:$A$2003,"<"&DATE(2026,L$5+1,1),'3. 5기 수입지출장부'!$E$5:$E$2003,">0")>0,"■","") | ... P15: =IF(COUNTIFS('3. 5기 수입지출장부'!$C$5:$C$2003,$C14,'3. 5기 수입지출장부'!$A$5:$A$2003,">="&DATE(2026,P$5,1),'3. 5기 수입지출장부'!$A$5:$A$2003,"<"&DATE(2026,P$5+1,1),'3. 5기 수입지출장부'!$E$5:$E$2003,">0")>0,"■","") | Q15: ='3. 5기 수입지출장부'!E196 -> 376000
B16: 6 | C16: 정책부회의비 | D16: 계획 | Q16: ='2. 5기_예산목간'!D30 -> 200000 | S16: =Q17/Q16 -> 0.675 | T16: 정책부
D17: 실적 | E17: =IF(COUNTIFS('3. 5기 수입지출장부'!$C$5:$C$2003,$C16,'3. 5기 수입지출장부'!$A$5:$A$2003,">="&DATE(2026,E$5,1),'3. 5기 수입지출장부'!$A$5:$A$2003,"<"&DATE(2026,E$5+1,1),'3. 5기 수입지출장부'!$E$5:$E$2003,">0")>0,"■","") | F17: =IF(COUNTIFS('3. 5기 수입지출장부'!$C$5:$C$2003,$C16,'3. 5기 수입지출장부'!$A$5:$A$2003,">="&DATE(2026,F$5,1),'3. 5기 수입지출장부'!$A$5:$A$2003,"<"&DATE(2026,F$5+1,1),'3. 5기 수입지출장부'!$E$5:$E$2003,">0")>0,"■","") | G17: =IF(COUNTIFS('3. 5기 수입지출장부'!$C$5:$C$2003,$C16,'3. 5기 수입지출장부'!$A$5:$A$2003,">="&DATE(2026,G$5,1),'3. 5기 수입지출장부'!$A$5:$A$2003,"<"&DATE(2026,G$5+1,1),'3. 5기 수입지출장부'!$E$5:$E$2003,">0")>0,"■","") | H17: =IF(COUNTIFS('3. 5기 수입지출장부'!$C$5:$C$2003,$C16,'3. 5기 수입지출장부'!$A$5:$A$2003,">="&DATE(2026,H$5,1),'3. 5기 수입지출장부'!$A$5:$A$2003,"<"&DATE(2026,H$5+1,1),'3. 5기 수입지출장부'!$E$5:$E$2003,">0")>0,"■","") | I17: =IF(COUNTIFS('3. 5기 수입지출장부'!$C$5:$C$2003,$C16,'3. 5기 수입지출장부'!$A$5:$A$2003,">="&DATE(2026,I$5,1),'3. 5기 수입지출장부'!$A$5:$A$2003,"<"&DATE(2026,I$5+1,1),'3. 5기 수입지출장부'!$E$5:$E$2003,">0")>0,"■","") | J17: =IF(COUNTIFS('3. 5기 수입지출장부'!$C$5:$C$2003,$C16,'3. 5기 수입지출장부'!$A$5:$A$2003,">="&DATE(2026,J$5,1),'3. 5기 수입지출장부'!$A$5:$A$2003,"<"&DATE(2026,J$5+1,1),'3. 5기 수입지출장부'!$E$5:$E$2003,">0")>0,"■","") | K17: =IF(COUNTIFS('3. 5기 수입지출장부'!$C$5:$C$2003,$C16,'3. 5기 수입지출장부'!$A$5:$A$2003,">="&DATE(2026,K$5,1),'3. 5기 수입지출장부'!$A$5:$A$2003,"<"&DATE(2026,K$5+1,1),'3. 5기 수입지출장부'!$E$5:$E$2003,">0")>0,"■","") | L17: =IF(COUNTIFS('3. 5기 수입지출장부'!$C$5:$C$2003,$C16,'3. 5기 수입지출장부'!$A$5:$A$2003,">="&DATE(2026,L$5,1),'3. 5기 수입지출장부'!$A$5:$A$2003,"<"&DATE(2026,L$5+1,1),'3. 5기 수입지출장부'!$E$5:$E$2003,">0")>0,"■","") -> ■ | ... P17: =IF(COUNTIFS('3. 5기 수입지출장부'!$C$5:$C$2003,$C16,'3. 5기 수입지출장부'!$A$5:$A$2003,">="&DATE(2026,P$5,1),'3. 5기 수입지출장부'!$A$5:$A$2003,"<"&DATE(2026,P$5+1,1),'3. 5기 수입지출장부'!$E$5:$E$2003,">0")>0,"■","") | Q17: ='3. 5기 수입지출장부'!E197 -> 135000
B18: 7 | C18: 대협회의비 | D18: 계획 | Q18: ='2. 5기_예산목간'!D31 -> 200000 | S18: =Q19/Q18 -> 0 | T18: 대협부
D19: 실적 | E19: =IF(COUNTIFS('3. 5기 수입지출장부'!$C$5:$C$2003,$C18,'3. 5기 수입지출장부'!$A$5:$A$2003,">="&DATE(2026,E$5,1),'3. 5기 수입지출장부'!$A$5:$A$2003,"<"&DATE(2026,E$5+1,1),'3. 5기 수입지출장부'!$E$5:$E$2003,">0")>0,"■","") | F19: =IF(COUNTIFS('3. 5기 수입지출장부'!$C$5:$C$2003,$C18,'3. 5기 수입지출장부'!$A$5:$A$2003,">="&DATE(2026,F$5,1),'3. 5기 수입지출장부'!$A$5:$A$2003,"<"&DATE(2026,F$5+1,1),'3. 5기 수입지출장부'!$E$5:$E$2003,">0")>0,"■","") | G19: =IF(COUNTIFS('3. 5기 수입지출장부'!$C$5:$C$2003,$C18,'3. 5기 수입지출장부'!$A$5:$A$2003,">="&DATE(2026,G$5,1),'3. 5기 수입지출장부'!$A$5:$A$2003,"<"&DATE(2026,G$5+1,1),'3. 5기 수입지출장부'!$E$5:$E$2003,">0")>0,"■","") | H19: =IF(COUNTIFS('3. 5기 수입지출장부'!$C$5:$C$2003,$C18,'3. 5기 수입지출장부'!$A$5:$A$2003,">="&DATE(2026,H$5,1),'3. 5기 수입지출장부'!$A$5:$A$2003,"<"&DATE(2026,H$5+1,1),'3. 5기 수입지출장부'!$E$5:$E$2003,">0")>0,"■","") | I19: =IF(COUNTIFS('3. 5기 수입지출장부'!$C$5:$C$2003,$C18,'3. 5기 수입지출장부'!$A$5:$A$2003,">="&DATE(2026,I$5,1),'3. 5기 수입지출장부'!$A$5:$A$2003,"<"&DATE(2026,I$5+1,1),'3. 5기 수입지출장부'!$E$5:$E$2003,">0")>0,"■","") | J19: =IF(COUNTIFS('3. 5기 수입지출장부'!$C$5:$C$2003,$C18,'3. 5기 수입지출장부'!$A$5:$A$2003,">="&DATE(2026,J$5,1),'3. 5기 수입지출장부'!$A$5:$A$2003,"<"&DATE(2026,J$5+1,1),'3. 5기 수입지출장부'!$E$5:$E$2003,">0")>0,"■","") | K19: =IF(COUNTIFS('3. 5기 수입지출장부'!$C$5:$C$2003,$C18,'3. 5기 수입지출장부'!$A$5:$A$2003,">="&DATE(2026,K$5,1),'3. 5기 수입지출장부'!$A$5:$A$2003,"<"&DATE(2026,K$5+1,1),'3. 5기 수입지출장부'!$E$5:$E$2003,">0")>0,"■","") | L19: =IF(COUNTIFS('3. 5기 수입지출장부'!$C$5:$C$2003,$C18,'3. 5기 수입지출장부'!$A$5:$A$2003,">="&DATE(2026,L$5,1),'3. 5기 수입지출장부'!$A$5:$A$2003,"<"&DATE(2026,L$5+1,1),'3. 5기 수입지출장부'!$E$5:$E$2003,">0")>0,"■","") | ... P19: =IF(COUNTIFS('3. 5기 수입지출장부'!$C$5:$C$2003,$C18,'3. 5기 수입지출장부'!$A$5:$A$2003,">="&DATE(2026,P$5,1),'3. 5기 수입지출장부'!$A$5:$A$2003,"<"&DATE(2026,P$5+1,1),'3. 5기 수입지출장부'!$E$5:$E$2003,">0")>0,"■","") | Q19: ='3. 5기 수입지출장부'!E198 -> 0
B20: 8 | C20: 교선회의비 | D20: 계획 | Q20: ='2. 5기_예산목간'!D32 -> 200000 | S20: =Q21/Q20 -> 0.675 | T20: 교선부
D21: 실적 | E21: =IF(COUNTIFS('3. 5기 수입지출장부'!$C$5:$C$2003,$C20,'3. 5기 수입지출장부'!$A$5:$A$2003,">="&DATE(2026,E$5,1),'3. 5기 수입지출장부'!$A$5:$A$2003,"<"&DATE(2026,E$5+1,1),'3. 5기 수입지출장부'!$E$5:$E$2003,">0")>0,"■","") | F21: =IF(COUNTIFS('3. 5기 수입지출장부'!$C$5:$C$2003,$C20,'3. 5기 수입지출장부'!$A$5:$A$2003,">="&DATE(2026,F$5,1),'3. 5기 수입지출장부'!$A$5:$A$2003,"<"&DATE(2026,F$5+1,1),'3. 5기 수입지출장부'!$E$5:$E$2003,">0")>0,"■","") | G21: =IF(COUNTIFS('3. 5기 수입지출장부'!$C$5:$C$2003,$C20,'3. 5기 수입지출장부'!$A$5:$A$2003,">="&DATE(2026,G$5,1),'3. 5기 수입지출장부'!$A$5:$A$2003,"<"&DATE(2026,G$5+1,1),'3. 5기 수입지출장부'!$E$5:$E$2003,">0")>0,"■","") | H21: =IF(COUNTIFS('3. 5기 수입지출장부'!$C$5:$C$2003,$C20,'3. 5기 수입지출장부'!$A$5:$A$2003,">="&DATE(2026,H$5,1),'3. 5기 수입지출장부'!$A$5:$A$2003,"<"&DATE(2026,H$5+1,1),'3. 5기 수입지출장부'!$E$5:$E$2003,">0")>0,"■","") | I21: =IF(COUNTIFS('3. 5기 수입지출장부'!$C$5:$C$2003,$C20,'3. 5기 수입지출장부'!$A$5:$A$2003,">="&DATE(2026,I$5,1),'3. 5기 수입지출장부'!$A$5:$A$2003,"<"&DATE(2026,I$5+1,1),'3. 5기 수입지출장부'!$E$5:$E$2003,">0")>0,"■","") | J21: =IF(COUNTIFS('3. 5기 수입지출장부'!$C$5:$C$2003,$C20,'3. 5기 수입지출장부'!$A$5:$A$2003,">="&DATE(2026,J$5,1),'3. 5기 수입지출장부'!$A$5:$A$2003,"<"&DATE(2026,J$5+1,1),'3. 5기 수입지출장부'!$E$5:$E$2003,">0")>0,"■","") | K21: =IF(COUNTIFS('3. 5기 수입지출장부'!$C$5:$C$2003,$C20,'3. 5기 수입지출장부'!$A$5:$A$2003,">="&DATE(2026,K$5,1),'3. 5기 수입지출장부'!$A$5:$A$2003,"<"&DATE(2026,K$5+1,1),'3. 5기 수입지출장부'!$E$5:$E$2003,">0")>0,"■","") | L21: =IF(COUNTIFS('3. 5기 수입지출장부'!$C$5:$C$2003,$C20,'3. 5기 수입지출장부'!$A$5:$A$2003,">="&DATE(2026,L$5,1),'3. 5기 수입지출장부'!$A$5:$A$2003,"<"&DATE(2026,L$5+1,1),'3. 5기 수입지출장부'!$E$5:$E$2003,">0")>0,"■","") -> ■ | ... P21: =IF(COUNTIFS('3. 5기 수입지출장부'!$C$5:$C$2003,$C20,'3. 5기 수입지출장부'!$A$5:$A$2003,">="&DATE(2026,P$5,1),'3. 5기 수입지출장부'!$A$5:$A$2003,"<"&DATE(2026,P$5+1,1),'3. 5기 수입지출장부'!$E$5:$E$2003,">0")>0,"■","") | Q21: ='3. 5기 수입지출장부'!E199 -> 135000
B22: 9 | C22: 의장단활동비 | D22: 계획 | Q22: ='2. 5기_예산목간'!D38 -> 3600000 | S22: =Q23/Q22 -> 0.80293889 | T22: 총무부
D23: 실적 | E23: =IF(COUNTIFS('3. 5기 수입지출장부'!$C$5:$C$2003,$C22,'3. 5기 수입지출장부'!$A$5:$A$2003,">="&DATE(2026,E$5,1),'3. 5기 수입지출장부'!$A$5:$A$2003,"<"&DATE(2026,E$5+1,1),'3. 5기 수입지출장부'!$E$5:$E$2003,">0")>0,"■","") | F23: =IF(COUNTIFS('3. 5기 수입지출장부'!$C$5:$C$2003,$C22,'3. 5기 수입지출장부'!$A$5:$A$2003,">="&DATE(2026,F$5,1),'3. 5기 수입지출장부'!$A$5:$A$2003,"<"&DATE(2026,F$5+1,1),'3. 5기 수입지출장부'!$E$5:$E$2003,">0")>0,"■","") | G23: =IF(COUNTIFS('3. 5기 수입지출장부'!$C$5:$C$2003,$C22,'3. 5기 수입지출장부'!$A$5:$A$2003,">="&DATE(2026,G$5,1),'3. 5기 수입지출장부'!$A$5:$A$2003,"<"&DATE(2026,G$5+1,1),'3. 5기 수입지출장부'!$E$5:$E$2003,">0")>0,"■","") -> ■ | H23: =IF(COUNTIFS('3. 5기 수입지출장부'!$C$5:$C$2003,$C22,'3. 5기 수입지출장부'!$A$5:$A$2003,">="&DATE(2026,H$5,1),'3. 5기 수입지출장부'!$A$5:$A$2003,"<"&DATE(2026,H$5+1,1),'3. 5기 수입지출장부'!$E$5:$E$2003,">0")>0,"■","") -> ■ | I23: =IF(COUNTIFS('3. 5기 수입지출장부'!$C$5:$C$2003,$C22,'3. 5기 수입지출장부'!$A$5:$A$2003,">="&DATE(2026,I$5,1),'3. 5기 수입지출장부'!$A$5:$A$2003,"<"&DATE(2026,I$5+1,1),'3. 5기 수입지출장부'!$E$5:$E$2003,">0")>0,"■","") -> ■ | J23: =IF(COUNTIFS('3. 5기 수입지출장부'!$C$5:$C$2003,$C22,'3. 5기 수입지출장부'!$A$5:$A$2003,">="&DATE(2026,J$5,1),'3. 5기 수입지출장부'!$A$5:$A$2003,"<"&DATE(2026,J$5+1,1),'3. 5기 수입지출장부'!$E$5:$E$2003,">0")>0,"■","") -> ■ | K23: =IF(COUNTIFS('3. 5기 수입지출장부'!$C$5:$C$2003,$C22,'3. 5기 수입지출장부'!$A$5:$A$2003,">="&DATE(2026,K$5,1),'3. 5기 수입지출장부'!$A$5:$A$2003,"<"&DATE(2026,K$5+1,1),'3. 5기 수입지출장부'!$E$5:$E$2003,">0")>0,"■","") -> ■ | L23: =IF(COUNTIFS('3. 5기 수입지출장부'!$C$5:$C$2003,$C22,'3. 5기 수입지출장부'!$A$5:$A$2003,">="&DATE(2026,L$5,1),'3. 5기 수입지출장부'!$A$5:$A$2003,"<"&DATE(2026,L$5+1,1),'3. 5기 수입지출장부'!$E$5:$E$2003,">0")>0,"■","") -> ■ | ... P23: =IF(COUNTIFS('3. 5기 수입지출장부'!$C$5:$C$2003,$C22,'3. 5기 수입지출장부'!$A$5:$A$2003,">="&DATE(2026,P$5,1),'3. 5기 수입지출장부'!$A$5:$A$2003,"<"&DATE(2026,P$5+1,1),'3. 5기 수입지출장부'!$E$5:$E$2003,">0")>0,"■","") | Q23: ='3. 5기 수입지출장부'!E201 -> 2890580
B24: 10 | C24: 조직활동비 | D24: 계획 | Q24: ='2. 5기_예산목간'!D39 -> 8000000 | S24: =Q25/Q24 -> 0.3625625 | T24: 조직부
D25: 실적 | E25: =IF(COUNTIFS('3. 5기 수입지출장부'!$C$5:$C$2003,$C24,'3. 5기 수입지출장부'!$A$5:$A$2003,">="&DATE(2026,E$5,1),'3. 5기 수입지출장부'!$A$5:$A$2003,"<"&DATE(2026,E$5+1,1),'3. 5기 수입지출장부'!$E$5:$E$2003,">0")>0,"■","") | F25: =IF(COUNTIFS('3. 5기 수입지출장부'!$C$5:$C$2003,$C24,'3. 5기 수입지출장부'!$A$5:$A$2003,">="&DATE(2026,F$5,1),'3. 5기 수입지출장부'!$A$5:$A$2003,"<"&DATE(2026,F$5+1,1),'3. 5기 수입지출장부'!$E$5:$E$2003,">0")>0,"■","") | G25: =IF(COUNTIFS('3. 5기 수입지출장부'!$C$5:$C$2003,$C24,'3. 5기 수입지출장부'!$A$5:$A$2003,">="&DATE(2026,G$5,1),'3. 5기 수입지출장부'!$A$5:$A$2003,"<"&DATE(2026,G$5+1,1),'3. 5기 수입지출장부'!$E$5:$E$2003,">0")>0,"■","") -> ■ | H25: =IF(COUNTIFS('3. 5기 수입지출장부'!$C$5:$C$2003,$C24,'3. 5기 수입지출장부'!$A$5:$A$2003,">="&DATE(2026,H$5,1),'3. 5기 수입지출장부'!$A$5:$A$2003,"<"&DATE(2026,H$5+1,1),'3. 5기 수입지출장부'!$E$5:$E$2003,">0")>0,"■","") -> ■ | I25: =IF(COUNTIFS('3. 5기 수입지출장부'!$C$5:$C$2003,$C24,'3. 5기 수입지출장부'!$A$5:$A$2003,">="&DATE(2026,I$5,1),'3. 5기 수입지출장부'!$A$5:$A$2003,"<"&DATE(2026,I$5+1,1),'3. 5기 수입지출장부'!$E$5:$E$2003,">0")>0,"■","") -> ■ | J25: =IF(COUNTIFS('3. 5기 수입지출장부'!$C$5:$C$2003,$C24,'3. 5기 수입지출장부'!$A$5:$A$2003,">="&DATE(2026,J$5,1),'3. 5기 수입지출장부'!$A$5:$A$2003,"<"&DATE(2026,J$5+1,1),'3. 5기 수입지출장부'!$E$5:$E$2003,">0")>0,"■","") | K25: =IF(COUNTIFS('3. 5기 수입지출장부'!$C$5:$C$2003,$C24,'3. 5기 수입지출장부'!$A$5:$A$2003,">="&DATE(2026,K$5,1),'3. 5기 수입지출장부'!$A$5:$A$2003,"<"&DATE(2026,K$5+1,1),'3. 5기 수입지출장부'!$E$5:$E$2003,">0")>0,"■","") -> ■ | L25: =IF(COUNTIFS('3. 5기 수입지출장부'!$C$5:$C$2003,$C24,'3. 5기 수입지출장부'!$A$5:$A$2003,">="&DATE(2026,L$5,1),'3. 5기 수입지출장부'!$A$5:$A$2003,"<"&DATE(2026,L$5+1,1),'3. 5기 수입지출장부'!$E$5:$E$2003,">0")>0,"■","") -> ■ | ... P25: =IF(COUNTIFS('3. 5기 수입지출장부'!$C$5:$C$2003,$C24,'3. 5기 수입지출장부'!$A$5:$A$2003,">="&DATE(2026,P$5,1),'3. 5기 수입지출장부'!$A$5:$A$2003,"<"&DATE(2026,P$5+1,1),'3. 5기 수입지출장부'!$E$5:$E$2003,">0")>0,"■","") | Q25: ='3. 5기 수입지출장부'!E202 -> 2900500
B26: =B24+1 -> 11 | C26: 조직원포상비 | D26: 계획 | Q26: ='2. 5기_예산목간'!D40 -> 300000 | S26: =Q27/Q26 -> 0 | T26: 총무부
D27: 실적 | E27: =IF(COUNTIFS('3. 5기 수입지출장부'!$C$5:$C$2003,$C26,'3. 5기 수입지출장부'!$A$5:$A$2003,">="&DATE(2026,E$5,1),'3. 5기 수입지출장부'!$A$5:$A$2003,"<"&DATE(2026,E$5+1,1),'3. 5기 수입지출장부'!$E$5:$E$2003,">0")>0,"■","") | F27: =IF(COUNTIFS('3. 5기 수입지출장부'!$C$5:$C$2003,$C26,'3. 5기 수입지출장부'!$A$5:$A$2003,">="&DATE(2026,F$5,1),'3. 5기 수입지출장부'!$A$5:$A$2003,"<"&DATE(2026,F$5+1,1),'3. 5기 수입지출장부'!$E$5:$E$2003,">0")>0,"■","") | G27: =IF(COUNTIFS('3. 5기 수입지출장부'!$C$5:$C$2003,$C26,'3. 5기 수입지출장부'!$A$5:$A$2003,">="&DATE(2026,G$5,1),'3. 5기 수입지출장부'!$A$5:$A$2003,"<"&DATE(2026,G$5+1,1),'3. 5기 수입지출장부'!$E$5:$E$2003,">0")>0,"■","") | H27: =IF(COUNTIFS('3. 5기 수입지출장부'!$C$5:$C$2003,$C26,'3. 5기 수입지출장부'!$A$5:$A$2003,">="&DATE(2026,H$5,1),'3. 5기 수입지출장부'!$A$5:$A$2003,"<"&DATE(2026,H$5+1,1),'3. 5기 수입지출장부'!$E$5:$E$2003,">0")>0,"■","") | I27: =IF(COUNTIFS('3. 5기 수입지출장부'!$C$5:$C$2003,$C26,'3. 5기 수입지출장부'!$A$5:$A$2003,">="&DATE(2026,I$5,1),'3. 5기 수입지출장부'!$A$5:$A$2003,"<"&DATE(2026,I$5+1,1),'3. 5기 수입지출장부'!$E$5:$E$2003,">0")>0,"■","") | J27: =IF(COUNTIFS('3. 5기 수입지출장부'!$C$5:$C$2003,$C26,'3. 5기 수입지출장부'!$A$5:$A$2003,">="&DATE(2026,J$5,1),'3. 5기 수입지출장부'!$A$5:$A$2003,"<"&DATE(2026,J$5+1,1),'3. 5기 수입지출장부'!$E$5:$E$2003,">0")>0,"■","") | K27: =IF(COUNTIFS('3. 5기 수입지출장부'!$C$5:$C$2003,$C26,'3. 5기 수입지출장부'!$A$5:$A$2003,">="&DATE(2026,K$5,1),'3. 5기 수입지출장부'!$A$5:$A$2003,"<"&DATE(2026,K$5+1,1),'3. 5기 수입지출장부'!$E$5:$E$2003,">0")>0,"■","") | L27: =IF(COUNTIFS('3. 5기 수입지출장부'!$C$5:$C$2003,$C26,'3. 5기 수입지출장부'!$A$5:$A$2003,">="&DATE(2026,L$5,1),'3. 5기 수입지출장부'!$A$5:$A$2003,"<"&DATE(2026,L$5+1,1),'3. 5기 수입지출장부'!$E$5:$E$2003,">0")>0,"■","") | ... P27: =IF(COUNTIFS('3. 5기 수입지출장부'!$C$5:$C$2003,$C26,'3. 5기 수입지출장부'!$A$5:$A$2003,">="&DATE(2026,P$5,1),'3. 5기 수입지출장부'!$A$5:$A$2003,"<"&DATE(2026,P$5+1,1),'3. 5기 수입지출장부'!$E$5:$E$2003,">0")>0,"■","") | Q27: ='3. 5기 수입지출장부'!E203 -> 0
B28: 12 | C28: 선물비 | D28: 계획 | Q28: ='2. 5기_예산목간'!D41 -> 4000000 | S28: =Q29/Q28 -> 0 | T28: 조직부
D29: 실적 | E29: =IF(COUNTIFS('3. 5기 수입지출장부'!$C$5:$C$2003,$C28,'3. 5기 수입지출장부'!$A$5:$A$2003,">="&DATE(2026,E$5,1),'3. 5기 수입지출장부'!$A$5:$A$2003,"<"&DATE(2026,E$5+1,1),'3. 5기 수입지출장부'!$E$5:$E$2003,">0")>0,"■","") | F29: =IF(COUNTIFS('3. 5기 수입지출장부'!$C$5:$C$2003,$C28,'3. 5기 수입지출장부'!$A$5:$A$2003,">="&DATE(2026,F$5,1),'3. 5기 수입지출장부'!$A$5:$A$2003,"<"&DATE(2026,F$5+1,1),'3. 5기 수입지출장부'!$E$5:$E$2003,">0")>0,"■","") | G29: =IF(COUNTIFS('3. 5기 수입지출장부'!$C$5:$C$2003,$C28,'3. 5기 수입지출장부'!$A$5:$A$2003,">="&DATE(2026,G$5,1),'3. 5기 수입지출장부'!$A$5:$A$2003,"<"&DATE(2026,G$5+1,1),'3. 5기 수입지출장부'!$E$5:$E$2003,">0")>0,"■","") | H29: =IF(COUNTIFS('3. 5기 수입지출장부'!$C$5:$C$2003,$C28,'3. 5기 수입지출장부'!$A$5:$A$2003,">="&DATE(2026,H$5,1),'3. 5기 수입지출장부'!$A$5:$A$2003,"<"&DATE(2026,H$5+1,1),'3. 5기 수입지출장부'!$E$5:$E$2003,">0")>0,"■","") | I29: =IF(COUNTIFS('3. 5기 수입지출장부'!$C$5:$C$2003,$C28,'3. 5기 수입지출장부'!$A$5:$A$2003,">="&DATE(2026,I$5,1),'3. 5기 수입지출장부'!$A$5:$A$2003,"<"&DATE(2026,I$5+1,1),'3. 5기 수입지출장부'!$E$5:$E$2003,">0")>0,"■","") | J29: =IF(COUNTIFS('3. 5기 수입지출장부'!$C$5:$C$2003,$C28,'3. 5기 수입지출장부'!$A$5:$A$2003,">="&DATE(2026,J$5,1),'3. 5기 수입지출장부'!$A$5:$A$2003,"<"&DATE(2026,J$5+1,1),'3. 5기 수입지출장부'!$E$5:$E$2003,">0")>0,"■","") | K29: =IF(COUNTIFS('3. 5기 수입지출장부'!$C$5:$C$2003,$C28,'3. 5기 수입지출장부'!$A$5:$A$2003,">="&DATE(2026,K$5,1),'3. 5기 수입지출장부'!$A$5:$A$2003,"<"&DATE(2026,K$5+1,1),'3. 5기 수입지출장부'!$E$5:$E$2003,">0")>0,"■","") | L29: =IF(COUNTIFS('3. 5기 수입지출장부'!$C$5:$C$2003,$C28,'3. 5기 수입지출장부'!$A$5:$A$2003,">="&DATE(2026,L$5,1),'3. 5기 수입지출장부'!$A$5:$A$2003,"<"&DATE(2026,L$5+1,1),'3. 5기 수입지출장부'!$E$5:$E$2003,">0")>0,"■","") | ... P29: =IF(COUNTIFS('3. 5기 수입지출장부'!$C$5:$C$2003,$C28,'3. 5기 수입지출장부'!$A$5:$A$2003,">="&DATE(2026,P$5,1),'3. 5기 수입지출장부'!$A$5:$A$2003,"<"&DATE(2026,P$5+1,1),'3. 5기 수입지출장부'!$E$5:$E$2003,">0")>0,"■","") | Q29: ='3. 5기 수입지출장부'!E204 -> 0
B30: 13 | C30: 조직원수련회비 | D30: 계획 | Q30: ='2. 5기_예산목간'!D42 -> 2300000 | S30: =Q31/Q30 -> 0 | T30: 조직부
D31: 실적 | E31: =IF(COUNTIFS('3. 5기 수입지출장부'!$C$5:$C$2003,$C30,'3. 5기 수입지출장부'!$A$5:$A$2003,">="&DATE(2026,E$5,1),'3. 5기 수입지출장부'!$A$5:$A$2003,"<"&DATE(2026,E$5+1,1),'3. 5기 수입지출장부'!$E$5:$E$2003,">0")>0,"■","") | F31: =IF(COUNTIFS('3. 5기 수입지출장부'!$C$5:$C$2003,$C30,'3. 5기 수입지출장부'!$A$5:$A$2003,">="&DATE(2026,F$5,1),'3. 5기 수입지출장부'!$A$5:$A$2003,"<"&DATE(2026,F$5+1,1),'3. 5기 수입지출장부'!$E$5:$E$2003,">0")>0,"■","") | G31: =IF(COUNTIFS('3. 5기 수입지출장부'!$C$5:$C$2003,$C30,'3. 5기 수입지출장부'!$A$5:$A$2003,">="&DATE(2026,G$5,1),'3. 5기 수입지출장부'!$A$5:$A$2003,"<"&DATE(2026,G$5+1,1),'3. 5기 수입지출장부'!$E$5:$E$2003,">0")>0,"■","") | H31: =IF(COUNTIFS('3. 5기 수입지출장부'!$C$5:$C$2003,$C30,'3. 5기 수입지출장부'!$A$5:$A$2003,">="&DATE(2026,H$5,1),'3. 5기 수입지출장부'!$A$5:$A$2003,"<"&DATE(2026,H$5+1,1),'3. 5기 수입지출장부'!$E$5:$E$2003,">0")>0,"■","") | I31: =IF(COUNTIFS('3. 5기 수입지출장부'!$C$5:$C$2003,$C30,'3. 5기 수입지출장부'!$A$5:$A$2003,">="&DATE(2026,I$5,1),'3. 5기 수입지출장부'!$A$5:$A$2003,"<"&DATE(2026,I$5+1,1),'3. 5기 수입지출장부'!$E$5:$E$2003,">0")>0,"■","") | J31: =IF(COUNTIFS('3. 5기 수입지출장부'!$C$5:$C$2003,$C30,'3. 5기 수입지출장부'!$A$5:$A$2003,">="&DATE(2026,J$5,1),'3. 5기 수입지출장부'!$A$5:$A$2003,"<"&DATE(2026,J$5+1,1),'3. 5기 수입지출장부'!$E$5:$E$2003,">0")>0,"■","") | K31: =IF(COUNTIFS('3. 5기 수입지출장부'!$C$5:$C$2003,$C30,'3. 5기 수입지출장부'!$A$5:$A$2003,">="&DATE(2026,K$5,1),'3. 5기 수입지출장부'!$A$5:$A$2003,"<"&DATE(2026,K$5+1,1),'3. 5기 수입지출장부'!$E$5:$E$2003,">0")>0,"■","") | L31: =IF(COUNTIFS('3. 5기 수입지출장부'!$C$5:$C$2003,$C30,'3. 5기 수입지출장부'!$A$5:$A$2003,">="&DATE(2026,L$5,1),'3. 5기 수입지출장부'!$A$5:$A$2003,"<"&DATE(2026,L$5+1,1),'3. 5기 수입지출장부'!$E$5:$E$2003,">0")>0,"■","") | ... P31: =IF(COUNTIFS('3. 5기 수입지출장부'!$C$5:$C$2003,$C30,'3. 5기 수입지출장부'!$A$5:$A$2003,">="&DATE(2026,P$5,1),'3. 5기 수입지출장부'!$A$5:$A$2003,"<"&DATE(2026,P$5+1,1),'3. 5기 수입지출장부'!$E$5:$E$2003,">0")>0,"■","") | Q31: ='3. 5기 수입지출장부'!E205 -> 0
B32: 14 | C32: 후원회원행사비 | D32: 계획 | Q32: ='2. 5기_예산목간'!D43 -> 0 | T32: 조직부
D33: 실적 | E33: =IF(COUNTIFS('3. 5기 수입지출장부'!$C$5:$C$2003,$C32,'3. 5기 수입지출장부'!$A$5:$A$2003,">="&DATE(2026,E$5,1),'3. 5기 수입지출장부'!$A$5:$A$2003,"<"&DATE(2026,E$5+1,1),'3. 5기 수입지출장부'!$E$5:$E$2003,">0")>0,"■","") | F33: =IF(COUNTIFS('3. 5기 수입지출장부'!$C$5:$C$2003,$C32,'3. 5기 수입지출장부'!$A$5:$A$2003,">="&DATE(2026,F$5,1),'3. 5기 수입지출장부'!$A$5:$A$2003,"<"&DATE(2026,F$5+1,1),'3. 5기 수입지출장부'!$E$5:$E$2003,">0")>0,"■","") | G33: =IF(COUNTIFS('3. 5기 수입지출장부'!$C$5:$C$2003,$C32,'3. 5기 수입지출장부'!$A$5:$A$2003,">="&DATE(2026,G$5,1),'3. 5기 수입지출장부'!$A$5:$A$2003,"<"&DATE(2026,G$5+1,1),'3. 5기 수입지출장부'!$E$5:$E$2003,">0")>0,"■","") | H33: =IF(COUNTIFS('3. 5기 수입지출장부'!$C$5:$C$2003,$C32,'3. 5기 수입지출장부'!$A$5:$A$2003,">="&DATE(2026,H$5,1),'3. 5기 수입지출장부'!$A$5:$A$2003,"<"&DATE(2026,H$5+1,1),'3. 5기 수입지출장부'!$E$5:$E$2003,">0")>0,"■","") | I33: =IF(COUNTIFS('3. 5기 수입지출장부'!$C$5:$C$2003,$C32,'3. 5기 수입지출장부'!$A$5:$A$2003,">="&DATE(2026,I$5,1),'3. 5기 수입지출장부'!$A$5:$A$2003,"<"&DATE(2026,I$5+1,1),'3. 5기 수입지출장부'!$E$5:$E$2003,">0")>0,"■","") | J33: =IF(COUNTIFS('3. 5기 수입지출장부'!$C$5:$C$2003,$C32,'3. 5기 수입지출장부'!$A$5:$A$2003,">="&DATE(2026,J$5,1),'3. 5기 수입지출장부'!$A$5:$A$2003,"<"&DATE(2026,J$5+1,1),'3. 5기 수입지출장부'!$E$5:$E$2003,">0")>0,"■","") | K33: =IF(COUNTIFS('3. 5기 수입지출장부'!$C$5:$C$2003,$C32,'3. 5기 수입지출장부'!$A$5:$A$2003,">="&DATE(2026,K$5,1),'3. 5기 수입지출장부'!$A$5:$A$2003,"<"&DATE(2026,K$5+1,1),'3. 5기 수입지출장부'!$E$5:$E$2003,">0")>0,"■","") | L33: =IF(COUNTIFS('3. 5기 수입지출장부'!$C$5:$C$2003,$C32,'3. 5기 수입지출장부'!$A$5:$A$2003,">="&DATE(2026,L$5,1),'3. 5기 수입지출장부'!$A$5:$A$2003,"<"&DATE(2026,L$5+1,1),'3. 5기 수입지출장부'!$E$5:$E$2003,">0")>0,"■","") | ... P33: =IF(COUNTIFS('3. 5기 수입지출장부'!$C$5:$C$2003,$C32,'3. 5기 수입지출장부'!$A$5:$A$2003,">="&DATE(2026,P$5,1),'3. 5기 수입지출장부'!$A$5:$A$2003,"<"&DATE(2026,P$5+1,1),'3. 5기 수입지출장부'!$E$5:$E$2003,">0")>0,"■","") | Q33: ='3. 5기 수입지출장부'!E206 -> 0
B34: =B32+1 -> 15 | C34: 정책활동비 | D34: 계획 | Q34: ='2. 5기_예산목간'!D45 -> 600000 | S34: =Q35/Q34 -> 0 | T34: 정책부
D35: 실적 | E35: =IF(COUNTIFS('3. 5기 수입지출장부'!$C$5:$C$2003,$C34,'3. 5기 수입지출장부'!$A$5:$A$2003,">="&DATE(2026,E$5,1),'3. 5기 수입지출장부'!$A$5:$A$2003,"<"&DATE(2026,E$5+1,1),'3. 5기 수입지출장부'!$E$5:$E$2003,">0")>0,"■","") | F35: =IF(COUNTIFS('3. 5기 수입지출장부'!$C$5:$C$2003,$C34,'3. 5기 수입지출장부'!$A$5:$A$2003,">="&DATE(2026,F$5,1),'3. 5기 수입지출장부'!$A$5:$A$2003,"<"&DATE(2026,F$5+1,1),'3. 5기 수입지출장부'!$E$5:$E$2003,">0")>0,"■","") | G35: =IF(COUNTIFS('3. 5기 수입지출장부'!$C$5:$C$2003,$C34,'3. 5기 수입지출장부'!$A$5:$A$2003,">="&DATE(2026,G$5,1),'3. 5기 수입지출장부'!$A$5:$A$2003,"<"&DATE(2026,G$5+1,1),'3. 5기 수입지출장부'!$E$5:$E$2003,">0")>0,"■","") | H35: =IF(COUNTIFS('3. 5기 수입지출장부'!$C$5:$C$2003,$C34,'3. 5기 수입지출장부'!$A$5:$A$2003,">="&DATE(2026,H$5,1),'3. 5기 수입지출장부'!$A$5:$A$2003,"<"&DATE(2026,H$5+1,1),'3. 5기 수입지출장부'!$E$5:$E$2003,">0")>0,"■","") | I35: =IF(COUNTIFS('3. 5기 수입지출장부'!$C$5:$C$2003,$C34,'3. 5기 수입지출장부'!$A$5:$A$2003,">="&DATE(2026,I$5,1),'3. 5기 수입지출장부'!$A$5:$A$2003,"<"&DATE(2026,I$5+1,1),'3. 5기 수입지출장부'!$E$5:$E$2003,">0")>0,"■","") | J35: =IF(COUNTIFS('3. 5기 수입지출장부'!$C$5:$C$2003,$C34,'3. 5기 수입지출장부'!$A$5:$A$2003,">="&DATE(2026,J$5,1),'3. 5기 수입지출장부'!$A$5:$A$2003,"<"&DATE(2026,J$5+1,1),'3. 5기 수입지출장부'!$E$5:$E$2003,">0")>0,"■","") | K35: =IF(COUNTIFS('3. 5기 수입지출장부'!$C$5:$C$2003,$C34,'3. 5기 수입지출장부'!$A$5:$A$2003,">="&DATE(2026,K$5,1),'3. 5기 수입지출장부'!$A$5:$A$2003,"<"&DATE(2026,K$5+1,1),'3. 5기 수입지출장부'!$E$5:$E$2003,">0")>0,"■","") | L35: =IF(COUNTIFS('3. 5기 수입지출장부'!$C$5:$C$2003,$C34,'3. 5기 수입지출장부'!$A$5:$A$2003,">="&DATE(2026,L$5,1),'3. 5기 수입지출장부'!$A$5:$A$2003,"<"&DATE(2026,L$5+1,1),'3. 5기 수입지출장부'!$E$5:$E$2003,">0")>0,"■","") | ... P35: =IF(COUNTIFS('3. 5기 수입지출장부'!$C$5:$C$2003,$C34,'3. 5기 수입지출장부'!$A$5:$A$2003,">="&DATE(2026,P$5,1),'3. 5기 수입지출장부'!$A$5:$A$2003,"<"&DATE(2026,P$5+1,1),'3. 5기 수입지출장부'!$E$5:$E$2003,">0")>0,"■","") | Q35: ='3. 5기 수입지출장부'!E207 -> 0
B36: 16 | C36: 대협활동비 | D36: 계획 | Q36: ='2. 5기_예산목간'!D47 -> 300000 | S36: =Q37/Q36 -> 0 | T36: 대협부
D37: 실적 | E37: =IF(COUNTIFS('3. 5기 수입지출장부'!$C$5:$C$2003,$C36,'3. 5기 수입지출장부'!$A$5:$A$2003,">="&DATE(2026,E$5,1),'3. 5기 수입지출장부'!$A$5:$A$2003,"<"&DATE(2026,E$5+1,1),'3. 5기 수입지출장부'!$E$5:$E$2003,">0")>0,"■","") | F37: =IF(COUNTIFS('3. 5기 수입지출장부'!$C$5:$C$2003,$C36,'3. 5기 수입지출장부'!$A$5:$A$2003,">="&DATE(2026,F$5,1),'3. 5기 수입지출장부'!$A$5:$A$2003,"<"&DATE(2026,F$5+1,1),'3. 5기 수입지출장부'!$E$5:$E$2003,">0")>0,"■","") | G37: =IF(COUNTIFS('3. 5기 수입지출장부'!$C$5:$C$2003,$C36,'3. 5기 수입지출장부'!$A$5:$A$2003,">="&DATE(2026,G$5,1),'3. 5기 수입지출장부'!$A$5:$A$2003,"<"&DATE(2026,G$5+1,1),'3. 5기 수입지출장부'!$E$5:$E$2003,">0")>0,"■","") | H37: =IF(COUNTIFS('3. 5기 수입지출장부'!$C$5:$C$2003,$C36,'3. 5기 수입지출장부'!$A$5:$A$2003,">="&DATE(2026,H$5,1),'3. 5기 수입지출장부'!$A$5:$A$2003,"<"&DATE(2026,H$5+1,1),'3. 5기 수입지출장부'!$E$5:$E$2003,">0")>0,"■","") | I37: =IF(COUNTIFS('3. 5기 수입지출장부'!$C$5:$C$2003,$C36,'3. 5기 수입지출장부'!$A$5:$A$2003,">="&DATE(2026,I$5,1),'3. 5기 수입지출장부'!$A$5:$A$2003,"<"&DATE(2026,I$5+1,1),'3. 5기 수입지출장부'!$E$5:$E$2003,">0")>0,"■","") | J37: =IF(COUNTIFS('3. 5기 수입지출장부'!$C$5:$C$2003,$C36,'3. 5기 수입지출장부'!$A$5:$A$2003,">="&DATE(2026,J$5,1),'3. 5기 수입지출장부'!$A$5:$A$2003,"<"&DATE(2026,J$5+1,1),'3. 5기 수입지출장부'!$E$5:$E$2003,">0")>0,"■","") | K37: =IF(COUNTIFS('3. 5기 수입지출장부'!$C$5:$C$2003,$C36,'3. 5기 수입지출장부'!$A$5:$A$2003,">="&DATE(2026,K$5,1),'3. 5기 수입지출장부'!$A$5:$A$2003,"<"&DATE(2026,K$5+1,1),'3. 5기 수입지출장부'!$E$5:$E$2003,">0")>0,"■","") | L37: =IF(COUNTIFS('3. 5기 수입지출장부'!$C$5:$C$2003,$C36,'3. 5기 수입지출장부'!$A$5:$A$2003,">="&DATE(2026,L$5,1),'3. 5기 수입지출장부'!$A$5:$A$2003,"<"&DATE(2026,L$5+1,1),'3. 5기 수입지출장부'!$E$5:$E$2003,">0")>0,"■","") | ... P37: =IF(COUNTIFS('3. 5기 수입지출장부'!$C$5:$C$2003,$C36,'3. 5기 수입지출장부'!$A$5:$A$2003,">="&DATE(2026,P$5,1),'3. 5기 수입지출장부'!$A$5:$A$2003,"<"&DATE(2026,P$5+1,1),'3. 5기 수입지출장부'!$E$5:$E$2003,">0")>0,"■","") | Q37: ='3. 5기 수입지출장부'!E208 -> 0
B38: 17 | C38: 대자보비 | D38: 계획 | Q38: ='2. 5기_예산목간'!D49 -> 500000 | S38: 0 | T38: 교선부
D39: 실적 | E39: =IF(COUNTIFS('3. 5기 수입지출장부'!$C$5:$C$2003,$C38,'3. 5기 수입지출장부'!$A$5:$A$2003,">="&DATE(2026,E$5,1),'3. 5기 수입지출장부'!$A$5:$A$2003,"<"&DATE(2026,E$5+1,1),'3. 5기 수입지출장부'!$E$5:$E$2003,">0")>0,"■","") | F39: =IF(COUNTIFS('3. 5기 수입지출장부'!$C$5:$C$2003,$C38,'3. 5기 수입지출장부'!$A$5:$A$2003,">="&DATE(2026,F$5,1),'3. 5기 수입지출장부'!$A$5:$A$2003,"<"&DATE(2026,F$5+1,1),'3. 5기 수입지출장부'!$E$5:$E$2003,">0")>0,"■","") | G39: =IF(COUNTIFS('3. 5기 수입지출장부'!$C$5:$C$2003,$C38,'3. 5기 수입지출장부'!$A$5:$A$2003,">="&DATE(2026,G$5,1),'3. 5기 수입지출장부'!$A$5:$A$2003,"<"&DATE(2026,G$5+1,1),'3. 5기 수입지출장부'!$E$5:$E$2003,">0")>0,"■","") | H39: =IF(COUNTIFS('3. 5기 수입지출장부'!$C$5:$C$2003,$C38,'3. 5기 수입지출장부'!$A$5:$A$2003,">="&DATE(2026,H$5,1),'3. 5기 수입지출장부'!$A$5:$A$2003,"<"&DATE(2026,H$5+1,1),'3. 5기 수입지출장부'!$E$5:$E$2003,">0")>0,"■","") | I39: =IF(COUNTIFS('3. 5기 수입지출장부'!$C$5:$C$2003,$C38,'3. 5기 수입지출장부'!$A$5:$A$2003,">="&DATE(2026,I$5,1),'3. 5기 수입지출장부'!$A$5:$A$2003,"<"&DATE(2026,I$5+1,1),'3. 5기 수입지출장부'!$E$5:$E$2003,">0")>0,"■","") | J39: =IF(COUNTIFS('3. 5기 수입지출장부'!$C$5:$C$2003,$C38,'3. 5기 수입지출장부'!$A$5:$A$2003,">="&DATE(2026,J$5,1),'3. 5기 수입지출장부'!$A$5:$A$2003,"<"&DATE(2026,J$5+1,1),'3. 5기 수입지출장부'!$E$5:$E$2003,">0")>0,"■","") | K39: =IF(COUNTIFS('3. 5기 수입지출장부'!$C$5:$C$2003,$C38,'3. 5기 수입지출장부'!$A$5:$A$2003,">="&DATE(2026,K$5,1),'3. 5기 수입지출장부'!$A$5:$A$2003,"<"&DATE(2026,K$5+1,1),'3. 5기 수입지출장부'!$E$5:$E$2003,">0")>0,"■","") | L39: =IF(COUNTIFS('3. 5기 수입지출장부'!$C$5:$C$2003,$C38,'3. 5기 수입지출장부'!$A$5:$A$2003,">="&DATE(2026,L$5,1),'3. 5기 수입지출장부'!$A$5:$A$2003,"<"&DATE(2026,L$5+1,1),'3. 5기 수입지출장부'!$E$5:$E$2003,">0")>0,"■","") | ... P39: =IF(COUNTIFS('3. 5기 수입지출장부'!$C$5:$C$2003,$C38,'3. 5기 수입지출장부'!$A$5:$A$2003,">="&DATE(2026,P$5,1),'3. 5기 수입지출장부'!$A$5:$A$2003,"<"&DATE(2026,P$5+1,1),'3. 5기 수입지출장부'!$E$5:$E$2003,">0")>0,"■","") | Q39: ='3. 5기 수입지출장부'!E209 -> 0
B40: 18 | C40: 유인물,현수막비 | D40: 계획 | Q40: ='2. 5기_예산목간'!D50 -> 400000 | S40: 0 | T40: 교선부
D41: 실적 | E41: =IF(COUNTIFS('3. 5기 수입지출장부'!$C$5:$C$2003,SUBSTITUTE($C40,", ",","),'3. 5기 수입지출장부'!$A$5:$A$2003,">="&DATE(2026,E$5,1),'3. 5기 수입지출장부'!$A$5:$A$2003,"<"&DATE(2026,E$5+1,1),'3. 5기 수입지출장부'!$E$5:$E$2003,">0")>0,"■","") | F41: =IF(COUNTIFS('3. 5기 수입지출장부'!$C$5:$C$2003,SUBSTITUTE($C40,", ",","),'3. 5기 수입지출장부'!$A$5:$A$2003,">="&DATE(2026,F$5,1),'3. 5기 수입지출장부'!$A$5:$A$2003,"<"&DATE(2026,F$5+1,1),'3. 5기 수입지출장부'!$E$5:$E$2003,">0")>0,"■","") | G41: =IF(COUNTIFS('3. 5기 수입지출장부'!$C$5:$C$2003,SUBSTITUTE($C40,", ",","),'3. 5기 수입지출장부'!$A$5:$A$2003,">="&DATE(2026,G$5,1),'3. 5기 수입지출장부'!$A$5:$A$2003,"<"&DATE(2026,G$5+1,1),'3. 5기 수입지출장부'!$E$5:$E$2003,">0")>0,"■","") | H41: =IF(COUNTIFS('3. 5기 수입지출장부'!$C$5:$C$2003,SUBSTITUTE($C40,", ",","),'3. 5기 수입지출장부'!$A$5:$A$2003,">="&DATE(2026,H$5,1),'3. 5기 수입지출장부'!$A$5:$A$2003,"<"&DATE(2026,H$5+1,1),'3. 5기 수입지출장부'!$E$5:$E$2003,">0")>0,"■","") | I41: =IF(COUNTIFS('3. 5기 수입지출장부'!$C$5:$C$2003,SUBSTITUTE($C40,", ",","),'3. 5기 수입지출장부'!$A$5:$A$2003,">="&DATE(2026,I$5,1),'3. 5기 수입지출장부'!$A$5:$A$2003,"<"&DATE(2026,I$5+1,1),'3. 5기 수입지출장부'!$E$5:$E$2003,">0")>0,"■","") | J41: =IF(COUNTIFS('3. 5기 수입지출장부'!$C$5:$C$2003,SUBSTITUTE($C40,", ",","),'3. 5기 수입지출장부'!$A$5:$A$2003,">="&DATE(2026,J$5,1),'3. 5기 수입지출장부'!$A$5:$A$2003,"<"&DATE(2026,J$5+1,1),'3. 5기 수입지출장부'!$E$5:$E$2003,">0")>0,"■","") | K41: =IF(COUNTIFS('3. 5기 수입지출장부'!$C$5:$C$2003,SUBSTITUTE($C40,", ",","),'3. 5기 수입지출장부'!$A$5:$A$2003,">="&DATE(2026,K$5,1),'3. 5기 수입지출장부'!$A$5:$A$2003,"<"&DATE(2026,K$5+1,1),'3. 5기 수입지출장부'!$E$5:$E$2003,">0")>0,"■","") | L41: =IF(COUNTIFS('3. 5기 수입지출장부'!$C$5:$C$2003,SUBSTITUTE($C40,", ",","),'3. 5기 수입지출장부'!$A$5:$A$2003,">="&DATE(2026,L$5,1),'3. 5기 수입지출장부'!$A$5:$A$2003,"<"&DATE(2026,L$5+1,1),'3. 5기 수입지출장부'!$E$5:$E$2003,">0")>0,"■","") | ... P41: =IF(COUNTIFS('3. 5기 수입지출장부'!$C$5:$C$2003,SUBSTITUTE($C40,", ",","),'3. 5기 수입지출장부'!$A$5:$A$2003,">="&DATE(2026,P$5,1),'3. 5기 수입지출장부'!$A$5:$A$2003,"<"&DATE(2026,P$5+1,1),'3. 5기 수입지출장부'!$E$5:$E$2003,">0")>0,"■","") | Q41: ='3. 5기 수입지출장부'!E210 -> 0
B42: =B40+1 -> 19 | C42: 가예산 | D42: 계획 | Q42: ='2. 5기_예산목간'!D53 -> 0 | S42: =Q43/Q42 -> #DIV/0! | T42: 총무부
D43: 실적 | E43: =IF(COUNTIFS('3. 5기 수입지출장부'!$B$5:$B$2003,$C42,'3. 5기 수입지출장부'!$A$5:$A$2003,">="&DATE(2026,E$5,1),'3. 5기 수입지출장부'!$A$5:$A$2003,"<"&DATE(2026,E$5+1,1),'3. 5기 수입지출장부'!$E$5:$E$2003,">0")>0,"■","") | F43: =IF(COUNTIFS('3. 5기 수입지출장부'!$B$5:$B$2003,$C42,'3. 5기 수입지출장부'!$A$5:$A$2003,">="&DATE(2026,F$5,1),'3. 5기 수입지출장부'!$A$5:$A$2003,"<"&DATE(2026,F$5+1,1),'3. 5기 수입지출장부'!$E$5:$E$2003,">0")>0,"■","") -> ■ | G43: =IF(COUNTIFS('3. 5기 수입지출장부'!$B$5:$B$2003,$C42,'3. 5기 수입지출장부'!$A$5:$A$2003,">="&DATE(2026,G$5,1),'3. 5기 수입지출장부'!$A$5:$A$2003,"<"&DATE(2026,G$5+1,1),'3. 5기 수입지출장부'!$E$5:$E$2003,">0")>0,"■","") | H43: =IF(COUNTIFS('3. 5기 수입지출장부'!$B$5:$B$2003,$C42,'3. 5기 수입지출장부'!$A$5:$A$2003,">="&DATE(2026,H$5,1),'3. 5기 수입지출장부'!$A$5:$A$2003,"<"&DATE(2026,H$5+1,1),'3. 5기 수입지출장부'!$E$5:$E$2003,">0")>0,"■","") | I43: =IF(COUNTIFS('3. 5기 수입지출장부'!$B$5:$B$2003,$C42,'3. 5기 수입지출장부'!$A$5:$A$2003,">="&DATE(2026,I$5,1),'3. 5기 수입지출장부'!$A$5:$A$2003,"<"&DATE(2026,I$5+1,1),'3. 5기 수입지출장부'!$E$5:$E$2003,">0")>0,"■","") | J43: =IF(COUNTIFS('3. 5기 수입지출장부'!$B$5:$B$2003,$C42,'3. 5기 수입지출장부'!$A$5:$A$2003,">="&DATE(2026,J$5,1),'3. 5기 수입지출장부'!$A$5:$A$2003,"<"&DATE(2026,J$5+1,1),'3. 5기 수입지출장부'!$E$5:$E$2003,">0")>0,"■","") | K43: =IF(COUNTIFS('3. 5기 수입지출장부'!$B$5:$B$2003,$C42,'3. 5기 수입지출장부'!$A$5:$A$2003,">="&DATE(2026,K$5,1),'3. 5기 수입지출장부'!$A$5:$A$2003,"<"&DATE(2026,K$5+1,1),'3. 5기 수입지출장부'!$E$5:$E$2003,">0")>0,"■","") | L43: =IF(COUNTIFS('3. 5기 수입지출장부'!$B$5:$B$2003,$C42,'3. 5기 수입지출장부'!$A$5:$A$2003,">="&DATE(2026,L$5,1),'3. 5기 수입지출장부'!$A$5:$A$2003,"<"&DATE(2026,L$5+1,1),'3. 5기 수입지출장부'!$E$5:$E$2003,">0")>0,"■","") | ... P43: =IF(COUNTIFS('3. 5기 수입지출장부'!$B$5:$B$2003,$C42,'3. 5기 수입지출장부'!$A$5:$A$2003,">="&DATE(2026,P$5,1),'3. 5기 수입지출장부'!$A$5:$A$2003,"<"&DATE(2026,P$5+1,1),'3. 5기 수입지출장부'!$E$5:$E$2003,">0")>0,"■","")
...

Sheet 2. 5기_예산목간
A4: 수 입 부 ( 26년 1월 ~26년 12월)
A5: 계 정 과 목 | D5: 편 성 금 액 | F5: 산 출 근 거
A6: 관 | B6: 항 | C6: 목 | D6: 금액 | E6: 편성비
A7: 수입 | B7: 의무금 | C7: 회비 | D7: ='4. 5기 수입상세 및 인원변동'!E18 -> 7340000 | E7: =D7/D$17 -> 0.17807715 | F7: ▷ 매달 입금에 따른 실시간 적용 금액
B8: 후원금 | C8: 회비 | D8: ='4. 5기 수입상세 및 인원변동'!F18 -> 7525000 | E8: =D8/D$17 -> 0.18256547 | F8: ▷ 매달 입금에 따른 실시간 적용 금액 (인원 변동)
B9: 이월금 | C9: 전년도 이월금 - (적립금) | D9: =23031391-D16 -> 13031391 | E9: =D9/D$17 -> 0.31615707 | F9: ▷ 4기 예산에 대한 이월금(23,031,391원)
B10: 소 계 | D10: =SUM(D7:D9) -> 27896391 | E10: =D10/D$17 -> 0.67679968
B11: 기타수입 | C11: 재정사업 | D11: ='4. 5기 수입상세 및 인원변동'!G20 -> 3308400 | E11: =D11/D$17 -> 0.080265726
C12: 잡수입2 | E12: =D12/D$17 -> 0
C13: 이자수입 | D13: ='4. 5기 수입상세 및 인원변동'!G22 -> 13300 | E13: =D13/D$17 -> 0.00032267385
C14: 소 계 | D14: =SUM(D11:D13) -> 3321700 | E14: =D14/D$17 -> 0.0805884
B15: 적립금 | C15: 적립금 | D15: 10000000 | E15: =D15/D$17 -> 0.24261192
C16: 소 계 | D16: =SUM(D15) -> 10000000 | E16: =D16/D$17 -> 0.24261192
A17: 합 계 | D17: =D16+D14+D10 -> 41218091 | E17: =E10+E14+E16 -> 1
A20: 지 출 부 ( 26년 1월 ~26년 12월)
A21: 계 정 과 목 | D21: 편 성 금 액 | F21: 산 출 근 거
A22: 관 | B22: 항 | C22: 목 | D22: 금액 | E22: 편성비
A23: 경조금 | B23: 경조금 | C23: 경조금 | D23: =3300000 -> 3300000 | E23: =D23/D$59 -> 0.080061932 | F23: ▷ 4기 평균 수준으로 계획
B24: 경조금 계 | D24: =D23 -> 3300000 | E24: =SUM(E23) -> 0.080061932
A25: 운영비 | B25: 여비 | C25: 국내여비 | D25: =214200*3*3 -> 1927800 | E25: =D25/D$59 -> 0.046770725 | F25: ▷ (214,200원 x 3명) x 3회 = 1,927,800원 (KTX 기준)
C26: 소 계 | D26: =SUM(D25) -> 1927800 | E26: =SUM(E25) -> 0.046770725
B27: 회의비 | C27: 운영위원회의비 | D27: =5000*9*12 -> 540000 | E27: =D27/D$59 -> 0.013101043 | F27: ▷ (5,000원 x 9명) x 12회 = 540,000원
C28: 대의원선거비 | D28: 1000000 | E28: =D28/D$59 -> 0.024261192
C29: 조직부회의비 | D29: =50000*8 -> 400000 | E29: =D29/D$59 -> 0.0097044766 | F29: ▷ (50,000원) x 8회 = 400,000원
C30: 정책부회의비 | D30: =50000*4 -> 200000 | E30: =D30/D$59 -> 0.0048522383 | F30: ▷ (50,000원) x 4회 = 200,000원
C31: 대협회의비 | D31: 200000 | E31: =D31/D$59 -> 0.0048522383 | F31: ▷ (50,000원) x 4회 = 200,000원
C32: 교선회의비 | D32: 200000 | E32: =D32/D$59 -> 0.0048522383 | F32: ▷ (50,000원) x 4회 = 200,000원
C33: 소계 | D33: =SUM(D27:D32) -> 2540000 | E33: =SUM(E27:E32) -> 0.061623426
B34: 사무비 | C34: 사무용품비 | D34: 0 | E34: =D34/D$59 -> 0
C35: 소 계 | D35: =D34 -> 0 | E35: =SUM(E34) -> 0
A36: 운영비 계 | D36: =D26+D33+D35 -> 4467800 | E36: =D36/D$59 -> 0.10839415
A37: 사업비 | B37: 사업부운영비 | C37: 의장단활동비 | D37: =300000*12 -> 3600000 | E37: =D37/D$59 -> 0.087340289 | F37: ▷ 900,000원 x 4분기 = 3,600,000원
C38: 소 계 | D38: =SUM(D37) -> 3600000 | E38: =SUM(E37) -> 0.087340289
B39: 조직사업비 | C39: 조직활동비 | D39: 8000000 | E39: =D39/D$59 -> 0.19408953 | F39: ▷ 조직사업 + 홍보사업 = 8,000,000원
C40: 조직원포상비 | D40: 300000 | E40: =D40/D$59 -> 0.0072783575 | F40: ▷ 100,000원 x 3명 = 300,000원
C41: 선물비 | D41: =20000*200 -> 4000000 | E41: =D41/D$59 -> 0.097044766 | F41: ▷ 20,000원 x 200명분(186명+@) = 4,000,000원
C42: 조직원수련회비 | D42: =50000*46 -> 2300000 | E42: =D42/D$59 -> 0.055800741 | F42: ▷ 50,000원 x 46명 = 2,300,000원
C43: 후원회원행사비 | D43: =15000*196-2940000 -> 0 | E43: =D43/D$59 -> 0
C44: 소 계 | D44: =SUM(D39:D43) -> 14600000 | E44: =D44/D$59 -> 0.3542134
B45: 정책사업비 | C45: 정책활동비 | D45: 600000 | E45: =D45/D$59 -> 0.014556715 | F45: ▷ 100,000원 x 6회 = 600,000원 (정책자료 수집, 여론수렴 자료화)
...

Sheet 3. 5기 수입지출장부
A1: THE 연구소 중심 5기 수입지출장부
A4: 날짜 | B4: 예산계정 | C4: 내용 및 목적 | D4: 수입 | E4: 지출 | F4: 수입(각출) | G4: 잔액 | H4: 내용 | I4: 정산일 | J4: 지불자 | K4: 입금은행명 | L4: 계좌번호 | M4: 기타 | N4: 확인
A5: 46073 | B5: 수입 | C5: 이월금 | D5: 23031391 | G5: =Table_1[[#This Row],[수입]] -> 23031391 | H5: 4기 회계연도 이월금 (26년 2월 최종 금액)
A6: 46073 | B6: 수입 | C6: 의무금 | D6: 1850000 | G6: =G5+Table_1[[#This Row],[수입]]-Table_1[[#This Row],[지출]] -> 24881391 | H6: 1월 조직 및 후원금 총액(소모임+집행부 미입금)
A7: 46077 | B7: 가예산 | C7: 조직활동비2 | E7: 60500 | G7: =G6+Table_1[[#This Row],[수입]]-Table_1[[#This Row],[지출]] -> 24820891 | H7: 현대차지부 정기대대 조직사업(다수영수증-일정다를수있음) | I7: 2026-03-07 | J7: 홍성민 | K7: 카뱅 | L7: 3333-05-4169942
A8: 46077 | B8: 가예산 | C8: 조직활동비2 | E8: 505800 | G8: =G7+Table_1[[#This Row],[수입]]-Table_1[[#This Row],[지출]] -> 24315091 | H8: 현대차지부 정기대대 조직사업(다수영수증-일정다를수있음) | I8: 2026-03-07 | J8: 최명규 | K8: 단위농협 | L8: 207070-52-074557
A9: 46077 | B9: 가예산 | C9: 조직활동비2 | E9: 73500 | G9: =G8+Table_1[[#This Row],[수입]]-Table_1[[#This Row],[지출]] -> 24241591 | H9: 현대차지부 정기대대 조직사업(다수영수증-일정다를수있음) | I9: 2026-03-07 | J9: 김봉수 | K9: 카뱅 | L9: 3333-11-3980780
A10: 46077 | B10: 가예산 | C10: 조직활동비2 | E10: 523400 | G10: =G9+Table_1[[#This Row],[수입]]-Table_1[[#This Row],[지출]] -> 23718191 | H10: 현대차지부 정기대대 조직사업(다수영수증-일정다를수있음) | I10: 2026-03-07 | J10: 박태순 | K10: 농협 | L10: 207073-52-008696
A11: 46077 | B11: 가예산 | C11: 조직활동비2 | E11: 202900 | G11: =G10+Table_1[[#This Row],[수입]]-Table_1[[#This Row],[지출]] -> 23515291 | H11: 현대차지부 정기대대 조직사업(다수영수증-일정다를수있음) | I11: 2026-03-07 | J11: 김경태 | K11: 국민 | L11: 4868-0101-315643
A12: 46077 | B12: 가예산 | C12: 조직활동비2 | E12: 520840 | G12: =G11+Table_1[[#This Row],[수입]]-Table_1[[#This Row],[지출]] -> 22994451 | H12: 현대차지부 정기대대 조직사업(다수영수증-일정다를수있음) | I12: 2026-03-07 | J12: 박보규 | K12: 농협 | L12: 207070-52-054882
A13: 46077 | B13: 가예산 | C13: 조직활동비2 | E13: 30600 | G13: =G12+Table_1[[#This Row],[수입]]-Table_1[[#This Row],[지출]] -> 22963851 | H13: 현대차지부 정기대대 조직사업(다수영수증-일정다를수있음) | I13: 2026-03-07 | J13: 정상화 | K13: 농협 | L13: 352-0341-4219-83
A14: 46077 | B14: 가예산 | C14: 조직활동비2 | E14: 872200 | G14: =G13+Table_1[[#This Row],[수입]]-Table_1[[#This Row],[지출]] -> 22091651 | H14: 현대차지부 정기대대 조직사업(다수영수증-일정다를수있음) | I14: 2026-03-07 | J14: 김성복 | K14: 신한 | L14: 110-147-074758
A15: 46077 | B15: 가예산 | C15: 조직활동비2 | E15: 124000 | G15: =G14+Table_1[[#This Row],[수입]]-Table_1[[#This Row],[지출]] -> 21967651 | H15: 현대차지부 정기대대 조직사업(다수영수증-일정다를수있음) | I15: 2026-03-07 | J15: 양수훈 | K15: 우리 | L15: 1002-641-955963
A16: 46078 | B16: 수입 | C16: 의무금 | D16: 1855000 | G16: =G15+Table_1[[#This Row],[수입]]-Table_1[[#This Row],[지출]] -> 23822651 | H16: 2월 조직 및 후원금 총액(소모임+집행부 미입금) | I16: 46078
A17: 46094 | B17: 총무 | C17: 경조금 | E17: 100000 | G17: =G16+Table_1[[#This Row],[수입]]-Table_1[[#This Row],[지출]] -> 23722651 | H17: 후원회원 강철원 장인상(광명중앙대병원 화환) | I17: 2026-03-13 | J17: 김성복 | K17: 농협 | L17: 179368-56-007449 | M17: 샤론꽃집/윤영순
A18: 46094 | B18: 총무 | C18: 경조금 | E18: 100000 | G18: =G17+Table_1[[#This Row],[수입]]-Table_1[[#This Row],[지출]] -> 23622651 | H18: 후원회원 강철원 장인상(조사)
A19: 46104 | B19: 조직강화 | C19: 조직활동비 | E19: 525000 | G19: =G18+Table_1[[#This Row],[수입]]-Table_1[[#This Row],[지출]] -> 23097651 | H19: 26-3차 정기총회 후 런치톡톡 35명, 15,000원 점심 | I19: 2026-03-23 | J19: 김성복 | K19: 신한 | L19: 110-147-074758
A20: 46106 | B20: 수입 | C20: 의무금 | D20: 1850000 | G20: =G19+Table_1[[#This Row],[수입]]-Table_1[[#This Row],[지출]] -> 24947651
A21: 46106 | B21: 총무 | C21: 의장단활동비 | E21: 13500 | G21: =G20+Table_1[[#This Row],[수입]]-Table_1[[#This Row],[지출]] -> 24934151 | H21: 의장단 회의 (박보규 외3명) | I21: 2026-03-25 | J21: 박보규 | K21: 농협 | L21: 207070-52-054882
A22: 46111 | B22: 총무 | C22: 의장단활동비 | E22: 80000 | G22: =G21+Table_1[[#This Row],[수입]]-Table_1[[#This Row],[지출]] -> 24854151 | H22: 의장단 및 교육위원 회의 | I22: 2026-03-30 | J22: 홍성민 | K22: 카뱅 | L22: 3333-05-4169942
A23: 46111 | B23: 총무 | C23: 의장단활동비 | E23: 104000 | G23: =G22+Table_1[[#This Row],[수입]]-Table_1[[#This Row],[지출]] -> 24750151 | H23: 조직사업(박보규 외 3명) | I23: 2026-03-31 | J23: 박보규 | K23: 농협 | L23: 207070-52-054882
A24: 46112 | B24: 총무 | C24: 의장단활동비 | E24: 176000 | G24: =G23+Table_1[[#This Row],[수입]]-Table_1[[#This Row],[지출]] -> 24574151 | H24: 운영위 점심식사(박보규 외 8명) | I24: 2026-03-31 | J24: 김성복 | K24: 신한 | L24: 110-147-074758
A25: 46119 | B25: 총무 | C25: 의장단활동비 | E25: 12700 | G25: =G24+Table_1[[#This Row],[수입]]-Table_1[[#This Row],[지출]] -> 24561451 | H25: 일반직 대의원 의견청취(홍성민 외 2명) | I25: 2026-04-08 | J25: 홍성민 | K25: 카뱅 | L25: 3333-05-4169942
A26: 46121 | B26: 조직강화 | C26: 조직활동비 | E26: 343700 | G26: =G25+Table_1[[#This Row],[수입]]-Table_1[[#This Row],[지출]] -> 24217751 | H26: 10대 집행부 저녁식사(박보규 외 8명) | I26: 2026-04-09 | J26: 박보규 | K26: 농협 | L26: 207070-52-054882
A27: 46125 | B27: 조직강화 | C27: 조직활동비 | E27: 61500 | G27: =G26+Table_1[[#This Row],[수입]]-Table_1[[#This Row],[지출]] -> 24156251 | H27: 11대 집행부 회의 (박보규 외 13명) | I27: 2026-04-13 | J27: 박보규 | K27: 농협 | L27: 207070-52-054882
A28: 46125 | B28: 조직강화 | C28: 조직활동비 | E28: 70900 | G28: =G27+Table_1[[#This Row],[수입]]-Table_1[[#This Row],[지출]] -> 24085351 | H28: 조직원 식사 및 회의 (박보규 외 2명) | I28: 2026-04-13 | J28: 박보규 | K28: 농협 | L28: 207070-52-054882
A29: 46127 | B29: 조직강화 | C29: 조직활동비 | E29: 24000 | G29: =G28+Table_1[[#This Row],[수입]]-Table_1[[#This Row],[지출]] -> 24061351 | H29: 조직원 회의 (박보규 외 4명) | I29: 2026-04-15 | J29: 박보규 | K29: 농협 | L29: 207070-52-054882 | O29: 임시대대 기간
A30: 46127 | B30: 조직강화 | C30: 조직활동비 | E30: 118600 | G30: =G29+Table_1[[#This Row],[수입]]-Table_1[[#This Row],[지출]] -> 23942751 | H30: 조직원 및 조직사업 저녁식사(박보규 외 7명) | I30: 2026-04-15 | J30: 박보규 | K30: 농협 | L30: 207070-52-054882
A31: 46127 | B31: 조직강화 | C31: 조직활동비 | E31: 25500 | G31: =G30+Table_1[[#This Row],[수입]]-Table_1[[#This Row],[지출]] -> 23917251 | H31: 조직사업 회의 (홍성민 외 3명) | I31: 2026-04-15 | J31: 홍성민 | K31: 카뱅 | L31: 3333-05-4169942
A32: 46127 | B32: 조직강화 | C32: 조직활동비 | E32: 26000 | G32: =G31+Table_1[[#This Row],[수입]]-Table_1[[#This Row],[지출]] -> 23891251 | H32: 조직사업 식사 (홍성민 외3명) | I32: 2026-04-15 | J32: 홍성민 | K32: 카뱅 | L32: 3333-05-4169942
A33: 46127 | B33: 조직강화 | C33: 조직활동비 | E33: 17500 | G33: =G32+Table_1[[#This Row],[수입]]-Table_1[[#This Row],[지출]] -> 23873751 | H33: 조직원 및 조직사업 회의 (김경태 외 4명) | I33: 2026-04-15 | J33: 김경태 | K33: 국민 | L33: 4868-0101-315643
A34: 46127 | B34: 조직강화 | C34: 조직활동비 | E34: 29300 | G34: =G33+Table_1[[#This Row],[수입]]-Table_1[[#This Row],[지출]] -> 23844451 | H34: 조직원 및 조직사업 회의 (김성복 외 6명) | I34: 2026-04-15 | J34: 김성복 | K34: 신한 | L34: 110-147-074758
A35: 46127 | B35: 조직강화 | C35: 조직활동비 | E35: 200000 | G35: =G34+Table_1[[#This Row],[수입]]-Table_1[[#This Row],[지출]] -> 23644451 | H35: 조직원 저녁식사 (김성복 외 10명) | I35: 2026-04-15 | J35: 김성복 | K35: 신한 | L35: 110-147-074758
A36: 46128 | B36: 조직강화 | C36: 조직활동비 | E36: 21700 | G36: =G35+Table_1[[#This Row],[수입]]-Table_1[[#This Row],[지출]] -> 23622751 | H36: 조직원 및 조직사업 (박보규 외 5명) | I36: 2026-04-16 | J36: 박보규 | K36: 농협 | L36: 207070-52-054882
A37: 46128 | B37: 조직강화 | C37: 조직활동비 | E37: 3000 | G37: =G36+Table_1[[#This Row],[수입]]-Table_1[[#This Row],[지출]] -> 23619751 | H37: 조직원 및 조직사업 (이현우) | I37: 2026-04-16 | J37: 홍성민 | K37: 카뱅 | L37: 3333-05-4169942
A38: 46128 | B38: 조직강화 | C38: 조직활동비 | E38: 18000 | G38: =G37+Table_1[[#This Row],[수입]]-Table_1[[#This Row],[지출]] -> 23601751 | H38: 조직원 및 조직사업 (홍성민 외 3명) | I38: 2026-04-16 | J38: 홍성민 | K38: 카뱅 | L38: 3333-05-4169942
A39: 46128 | B39: 조직강화 | C39: 조직활동비 | E39: 14600 | G39: =G38+Table_1[[#This Row],[수입]]-Table_1[[#This Row],[지출]] -> 23587151 | H39: 조직원 회의 (김성복 외 3명) | I39: 2026-04-16 | J39: 김성복 | K39: 신한 | L39: 110-147-074758
A40: 46128 | B40: 조직강화 | C40: 조직활동비 | E40: 92000 | G40: =G39+Table_1[[#This Row],[수입]]-Table_1[[#This Row],[지출]] -> 23495151 | H40: 조직대의원 뒷풀이 (지불자 김성복) | I40: 2026-04-16 | J40: 김성복 | K40: 신한 | L40: 110-147-074758
A41: 46128 | B41: 조직강화 | C41: 조직활동비 | E41: 200000 | G41: =G40+Table_1[[#This Row],[수입]]-Table_1[[#This Row],[지출]] -> 23295151 | H41: 조직대의원 뒷풀이 (지불자 김성복) | I41: 2026-04-16 | J41: 김성복 | K41: 신한 | L41: 110-147-074758
... A45: 46128 | B45: 조직강화 | C45: 조직활동비 | E45: 67000 | G45: =G44+Table_1[[#This Row],[수입]]-Table_1[[#This Row],[지출]] -> 23071151 | H45: 조직대의원 뒷풀이 (지불자 박보규) | I45: 2026-04-16 | J45: 박보규 | K45: 농협 | L45: 207070-52-054882
...

Sheet 4. 5기 수입상세 및 인원변동
B2: 2026년 5기 수입 금액 정리
C5: 조직원 수 | D5: 후원회원 수 | E5: 조직원 입금 | F5: 후원회원 입금 | G5: 입금액 | H5: 비 고
B6: 1월 | C6: 45 | D6: 189 | E6: =C6*20000 -> 900000 | F6: =189*5000+5000 -> 950000 | G6: =SUM(E6:F6) -> 1850000 | H6: 후원회원
B7: 2월 | C7: 46 | D7: 186 | E7: =C7*20000 -> 920000 | F7: =D7*5000+5000 -> 935000 | G7: =E7+F7 -> 1855000 | H7: 조직원 탈퇴(1):박준성 조직원 가입(2):임재진,유규석 후원회원탈퇴(4):김동우, 임선우, 임재진, 유규석 후원회원 가입(1):박준성 후원회원 중 10,000원 후원 1명 존재
B8: 3월 | C8: 46 | D8: 185 | E8: =C8*20000 -> 920000 | F8: =D8*5000+5000 -> 930000 | G8: =E8+F8 -> 1850000 | H8: 후원회원탈퇴(1) : 김태문(미공제)
B9: 4월 | C9: 46 | D9: 186 | E9: =C9*20000 -> 920000 | F9: =D9*5000+5000 -> 935000 | G9: =E9+F9 -> 1855000 | H9: 4월14일 - 윤희성 후원회원 가입 (회계처리완) 4월 22일 - 김정환 후원회원 가입 (회계처리 기간이 지나 5월 회계처리예정)
B10: 5월 | C10: 46 | D10: 187 | E10: =C10*20000 -> 920000 | F10: =D10*5000+5000 -> 940000 | G10: =E10+F10 -> 1860000 | H10: 김정환 후원회원 5월 가입 처리 (회계)
B11: 6월 | C11: 46 | D11: 187 | E11: =C11*20000 -> 920000 | F11: =D11*5000+5000 -> 940000 | G11: =E11+F11 -> 1860000 | H11: 6월20일 - 소지섭 연구원(회계처리 기간이 지나 7월 회계처리예정)
B12: 7월 | C12: 46 | D12: 188 | E12: =C12*20000 -> 920000 | F12: =D12*5000+5000 -> 945000 | G12: =E12+F12 -> 1865000 | H12: 소지섭 연구원 - 회계처리 기간이 지나 7월 회계처리완료
B13: 8월 | C13: 46 | D13: 189 | E13: =C13*20000 -> 920000 | F13: =D13*5000+5000 -> 950000 | G13: =E13+F13 -> 1870000 | H13: 정양민 연구원 - 8월 5일 가입 처리 완 (회계)
B14: 9월
B15: 10월
B16: 11월
B17: 12월
B18: 회비(합계) | E18: =SUM(E6:E17) -> 7340000 | F18: =SUM(F6:F17) -> 7525000 | G18: =SUM(G6:G17) -> 14865000
B20: 재정사업(합계) | G20: =SUMIFS('3. 5기 수입지출장부'!$D$5:$D$2003,'3. 5기 수입지출장부'!$C$5:$C$2003,"재정사업") -> 3308400
B22: 이자(합계) | G22: =SUMIFS('3. 5기 수입지출장부'!$D$5:$D$2003,'3. 5기 수입지출장부'!$C$5:$C$2003,"이자수입") -> 13300
B24: 총수입 | G24: =G18+G20+G22 -> 18186700 | H24: 회비+재정사업+예금이자

Sheet 5. 대시보드
A1: THE 연구소 5기 예산 대비 실적 대시보드
A2: 기준: 2026-02-20 ~ 2026-09-01 실적 반영 · 회계연도 경과 약 67%
B4: 총 편성예산 | D4: 공식 지출실적 | F4: 현재 잔액 | I4: 공식예산 집행률 | K4: 가예산 별도집행
B5: ='2. 5기_예산목간'!D59 -> 41218091 | D5: =SUM('3. 5기 수입지출장부'!E192:E210) -> 7403080 | F5: =LOOKUP(9.99E+307,Table_1[잔액]) -> 30901271 | I5: =D5/B5 -> 0.17960754 | K5: =SUM(Table_1[지출])-D5 -> 2913740
A9: 세부 항목별 예산 집행 현황 (19개 항목, 예산목간 순서)
B10: 관 | C10: 항목 | D10: 예산 | E10: 실적 | F10: 잔액 | G10: 집행률
B11: 경조금 | C11: 경조금 | D11: ='3. 5기 수입지출장부'!D192 -> 3300000 | E11: ='3. 5기 수입지출장부'!E192 -> 800000 | F11: ='3. 5기 수입지출장부'!F192 -> 2500000 | G11: =IFERROR(E11/D11,0) -> 0.24242424
B12: 운영비 | C12: 국내여비 | D12: ='3. 5기 수입지출장부'!D193 -> 1927800 | E12: ='3. 5기 수입지출장부'!E193 -> 0 | F12: ='3. 5기 수입지출장부'!F193 -> 1927800 | G12: =IFERROR(E12/D12,0) -> 0
B13: 운영비 | C13: 운영위원회의비 | D13: ='3. 5기 수입지출장부'!D194 -> 540000 | E13: ='3. 5기 수입지출장부'!E194 -> 166000 | F13: ='3. 5기 수입지출장부'!F194 -> 374000 | G13: =IFERROR(E13/D13,0) -> 0.30740741
B14: 운영비 | C14: 대의원선거비 | D14: ='3. 5기 수입지출장부'!D195 -> 1000000 | E14: ='3. 5기 수입지출장부'!E195 -> 0 | F14: ='3. 5기 수입지출장부'!F195 -> 1000000 | G14: =IFERROR(E14/D14,0) -> 0
B15: 운영비 | C15: 조직부회의비 | D15: ='3. 5기 수입지출장부'!D196 -> 400000 | E15: ='3. 5기 수입지출장부'!E196 -> 376000 | F15: ='3. 5기 수입지출장부'!F196 -> 24000 | G15: =IFERROR(E15/D15,0) -> 0.94
B16: 운영비 | C16: 정책부회의비 | D16: ='3. 5기 수입지출장부'!D197 -> 200000 | E16: ='3. 5기 수입지출장부'!E197 -> 135000 | F16: ='3. 5기 수입지출장부'!F197 -> 65000 | G16: =IFERROR(E16/D16,0) -> 0.675
B17: 운영비 | C17: 대협회의비 | D17: ='3. 5기 수입지출장부'!D198 -> 200000 | E17: ='3. 5기 수입지출장부'!E198 -> 0 | F17: ='3. 5기 수입지출장부'!F198 -> 200000 | G17: =IFERROR(E17/D17,0) -> 0
B18: 운영비 | C18: 교선회의비 | D18: ='3. 5기 수입지출장부'!D199 -> 200000 | E18: ='3. 5기 수입지출장부'!E199 -> 135000 | F18: ='3. 5기 수입지출장부'!F199 -> 65000 | G18: =IFERROR(E18/D18,0) -> 0.675
B19: 운영비 | C19: 사무용품비 | D19: ='3. 5기 수입지출장부'!D200 -> 0 | E19: ='3. 5기 수입지출장부'!E200 -> 0 | F19: ='3. 5기 수입지출장부'!F200 -> 0 | G19: =IFERROR(E19/D19,0) -> 0
B20: 사업비 | C20: 의장단활동비 | D20: ='3. 5기 수입지출장부'!D201 -> 3600000 | E20: ='3. 5기 수입지출장부'!E201 -> 2890580 | F20: ='3. 5기 수입지출장부'!F201 -> 709420 | G20: =IFERROR(E20/D20,0) -> 0.80293889
B21: 사업비 | C21: 조직활동비 | D21: ='3. 5기 수입지출장부'!D202 -> 8000000 | E21: ='3. 5기 수입지출장부'!E202 -> 2900500 | F21: ='3. 5기 수입지출장부'!F202 -> 5099500 | G21: =IFERROR(E21/D21,0) -> 0.3625625
B22: 사업비 | C22: 조직원포상비 | D22: ='3. 5기 수입지출장부'!D203 -> 300000 | E22: ='3. 5기 수입지출장부'!E203 -> 0 | F22: ='3. 5기 수입지출장부'!F203 -> 300000 | G22: =IFERROR(E22/D22,0) -> 0
... B29: 사업비 | C29: 유인물,현수막비 | D29: ='3. 5기 수입지출장부'!D210 -> 400000 | E29: ='3. 5기 수입지출장부'!E210 -> 0 | F29: ='3. 5기 수입지출장부'!F210 -> 400000 | G29: =IFERROR(E29/D29,0) -> 0
A31: ※ 가예산(조직활동비2 등)은 공식 사업계획(2. 5기_예산목간 시트)에 편성되지 않은 별도 집행 항목으로, 위 공식예산 집행률 계산에서 제외되어 있습니다. 예산 0원 항목(사무용품비, 후원회원행사비)의 집행률은 0%로 표시됩니다.
